test
Not Found: /
Not Found: /favicon.ico
Not Found: /favicon.ico
Internal Server Error: /np/
Traceback (most recent call last):
  File "/home/miroslav/PycharmProjects/Project_nova_poshta-simulator/venv/lib/python3.6/site-packages/django/template/base.py", line 475, in parse
    compile_func = self.tags[command]
KeyError: 'endif'

During handling of the above exception, another exception occurred:

Traceback (most recent call last):
  File "/home/miroslav/PycharmProjects/Project_nova_poshta-simulator/venv/lib/python3.6/site-packages/django/core/handlers/exception.py", line 35, in inner
    response = get_response(request)
  File "/home/miroslav/PycharmProjects/Project_nova_poshta-simulator/venv/lib/python3.6/site-packages/django/core/handlers/base.py", line 128, in _get_response
    response = self.process_exception_by_middleware(e, request)
  File "/home/miroslav/PycharmProjects/Project_nova_poshta-simulator/venv/lib/python3.6/site-packages/django/core/handlers/base.py", line 126, in _get_response
    response = wrapped_callback(request, *callback_args, **callback_kwargs)
  File "/home/miroslav/PycharmProjects/Project_nova_poshta-simulator/venv/lib/python3.6/site-packages/django/views/generic/base.py", line 69, in view
    return self.dispatch(request, *args, **kwargs)
  File "/home/miroslav/PycharmProjects/Project_nova_poshta-simulator/venv/lib/python3.6/site-packages/django/views/generic/base.py", line 89, in dispatch
    return handler(request, *args, **kwargs)
  File "/home/miroslav/PycharmProjects/Project_nova_poshta-simulator/nova_poshta/main/views.py", line 33, in get
    return render(request, self.template_name, {})
  File "/home/miroslav/PycharmProjects/Project_nova_poshta-simulator/venv/lib/python3.6/site-packages/django/shortcuts.py", line 36, in render
    content = loader.render_to_string(template_name, context, request, using=using)
  File "/home/miroslav/PycharmProjects/Project_nova_poshta-simulator/venv/lib/python3.6/site-packages/django/template/loader.py", line 61, in render_to_string
    template = get_template(template_name, using=using)
  File "/home/miroslav/PycharmProjects/Project_nova_poshta-simulator/venv/lib/python3.6/site-packages/django/template/loader.py", line 15, in get_template
    return engine.get_template(template_name)
  File "/home/miroslav/PycharmProjects/Project_nova_poshta-simulator/venv/lib/python3.6/site-packages/django/template/backends/django.py", line 34, in get_template
    return Template(self.engine.get_template(template_name), self)
  File "/home/miroslav/PycharmProjects/Project_nova_poshta-simulator/venv/lib/python3.6/site-packages/django/template/engine.py", line 144, in get_template
    template, origin = self.find_template(template_name)
  File "/home/miroslav/PycharmProjects/Project_nova_poshta-simulator/venv/lib/python3.6/site-packages/django/template/engine.py", line 126, in find_template
    template = loader.get_template(name, skip=skip)
  File "/home/miroslav/PycharmProjects/Project_nova_poshta-simulator/venv/lib/python3.6/site-packages/django/template/loaders/base.py", line 30, in get_template
    contents, origin, origin.template_name, self.engine,
  File "/home/miroslav/PycharmProjects/Project_nova_poshta-simulator/venv/lib/python3.6/site-packages/django/template/base.py", line 160, in __init__
    self.nodelist = self.compile_nodelist()
  File "/home/miroslav/PycharmProjects/Project_nova_poshta-simulator/venv/lib/python3.6/site-packages/django/template/base.py", line 198, in compile_nodelist
    return parser.parse()
  File "/home/miroslav/PycharmProjects/Project_nova_poshta-simulator/venv/lib/python3.6/site-packages/django/template/base.py", line 483, in parse
    raise self.error(token, e)
  File "/home/miroslav/PycharmProjects/Project_nova_poshta-simulator/venv/lib/python3.6/site-packages/django/template/base.py", line 481, in parse
    compiled_result = compile_func(self, token)
  File "/home/miroslav/PycharmProjects/Project_nova_poshta-simulator/venv/lib/python3.6/site-packages/django/template/defaulttags.py", line 956, in do_if
    nodelist = parser.parse(('elif', 'else', 'endif'))
  File "/home/miroslav/PycharmProjects/Project_nova_poshta-simulator/venv/lib/python3.6/site-packages/django/template/base.py", line 483, in parse
    raise self.error(token, e)
  File "/home/miroslav/PycharmProjects/Project_nova_poshta-simulator/venv/lib/python3.6/site-packages/django/template/base.py", line 481, in parse
    compiled_result = compile_func(self, token)
  File "/home/miroslav/PycharmProjects/Project_nova_poshta-simulator/venv/lib/python3.6/site-packages/django/template/defaulttags.py", line 815, in do_for
    nodelist_loop = parser.parse(('empty', 'endfor',))
  File "/home/miroslav/PycharmProjects/Project_nova_poshta-simulator/venv/lib/python3.6/site-packages/django/template/base.py", line 477, in parse
    self.invalid_block_tag(token, command, parse_until)
  File "/home/miroslav/PycharmProjects/Project_nova_poshta-simulator/venv/lib/python3.6/site-packages/django/template/base.py", line 533, in invalid_block_tag
    get_text_list(["'%s'" % p for p in parse_until], 'or'),
django.template.exceptions.TemplateSyntaxError: Invalid block tag on line 44: 'endif', expected 'empty' or 'endfor'. Did you forget to register or load this tag?
Internal Server Error: /np/
Traceback (most recent call last):
  File "/home/miroslav/PycharmProjects/Project_nova_poshta-simulator/venv/lib/python3.6/site-packages/django/core/handlers/exception.py", line 35, in inner
    response = get_response(request)
  File "/home/miroslav/PycharmProjects/Project_nova_poshta-simulator/venv/lib/python3.6/site-packages/django/core/handlers/base.py", line 128, in _get_response
    response = self.process_exception_by_middleware(e, request)
  File "/home/miroslav/PycharmProjects/Project_nova_poshta-simulator/venv/lib/python3.6/site-packages/django/core/handlers/base.py", line 126, in _get_response
    response = wrapped_callback(request, *callback_args, **callback_kwargs)
  File "/home/miroslav/PycharmProjects/Project_nova_poshta-simulator/venv/lib/python3.6/site-packages/django/views/generic/base.py", line 69, in view
    return self.dispatch(request, *args, **kwargs)
  File "/home/miroslav/PycharmProjects/Project_nova_poshta-simulator/venv/lib/python3.6/site-packages/django/views/generic/base.py", line 89, in dispatch
    return handler(request, *args, **kwargs)
  File "/home/miroslav/PycharmProjects/Project_nova_poshta-simulator/nova_poshta/main/views.py", line 25, in get
    print(Vehicle.objects.first().max_weight)
AttributeError: 'NoneType' object has no attribute 'max_weight'
Internal Server Error: /np/
Traceback (most recent call last):
  File "/home/miroslav/PycharmProjects/Project_nova_poshta-simulator/venv/lib/python3.6/site-packages/django/core/handlers/exception.py", line 35, in inner
    response = get_response(request)
  File "/home/miroslav/PycharmProjects/Project_nova_poshta-simulator/venv/lib/python3.6/site-packages/django/core/handlers/base.py", line 128, in _get_response
    response = self.process_exception_by_middleware(e, request)
  File "/home/miroslav/PycharmProjects/Project_nova_poshta-simulator/venv/lib/python3.6/site-packages/django/core/handlers/base.py", line 126, in _get_response
    response = wrapped_callback(request, *callback_args, **callback_kwargs)
  File "/home/miroslav/PycharmProjects/Project_nova_poshta-simulator/venv/lib/python3.6/site-packages/django/views/generic/base.py", line 69, in view
    return self.dispatch(request, *args, **kwargs)
  File "/home/miroslav/PycharmProjects/Project_nova_poshta-simulator/venv/lib/python3.6/site-packages/django/views/generic/base.py", line 89, in dispatch
    return handler(request, *args, **kwargs)
  File "/home/miroslav/PycharmProjects/Project_nova_poshta-simulator/nova_poshta/main/views.py", line 25, in get
    print(Vehicle.objects.first().max_weight)
AttributeError: 'NoneType' object has no attribute 'max_weight'
Internal Server Error: /np/
Traceback (most recent call last):
  File "/home/miroslav/PycharmProjects/Project_nova_poshta-simulator/venv/lib/python3.6/site-packages/django/core/handlers/exception.py", line 35, in inner
    response = get_response(request)
  File "/home/miroslav/PycharmProjects/Project_nova_poshta-simulator/venv/lib/python3.6/site-packages/django/core/handlers/base.py", line 128, in _get_response
    response = self.process_exception_by_middleware(e, request)
  File "/home/miroslav/PycharmProjects/Project_nova_poshta-simulator/venv/lib/python3.6/site-packages/django/core/handlers/base.py", line 126, in _get_response
    response = wrapped_callback(request, *callback_args, **callback_kwargs)
  File "/home/miroslav/PycharmProjects/Project_nova_poshta-simulator/venv/lib/python3.6/site-packages/django/views/generic/base.py", line 69, in view
    return self.dispatch(request, *args, **kwargs)
  File "/home/miroslav/PycharmProjects/Project_nova_poshta-simulator/venv/lib/python3.6/site-packages/django/views/generic/base.py", line 89, in dispatch
    return handler(request, *args, **kwargs)
  File "/home/miroslav/PycharmProjects/Project_nova_poshta-simulator/nova_poshta/main/views.py", line 26, in get
    print(vehicle.max_weight)
AttributeError: 'NoneType' object has no attribute 'max_weight'
Internal Server Error: /np/
Traceback (most recent call last):
  File "/home/miroslav/PycharmProjects/Project_nova_poshta-simulator/venv/lib/python3.6/site-packages/django/core/handlers/exception.py", line 35, in inner
    response = get_response(request)
  File "/home/miroslav/PycharmProjects/Project_nova_poshta-simulator/venv/lib/python3.6/site-packages/django/core/handlers/base.py", line 128, in _get_response
    response = self.process_exception_by_middleware(e, request)
  File "/home/miroslav/PycharmProjects/Project_nova_poshta-simulator/venv/lib/python3.6/site-packages/django/core/handlers/base.py", line 126, in _get_response
    response = wrapped_callback(request, *callback_args, **callback_kwargs)
  File "/home/miroslav/PycharmProjects/Project_nova_poshta-simulator/venv/lib/python3.6/site-packages/django/views/generic/base.py", line 69, in view
    return self.dispatch(request, *args, **kwargs)
  File "/home/miroslav/PycharmProjects/Project_nova_poshta-simulator/venv/lib/python3.6/site-packages/django/views/generic/base.py", line 89, in dispatch
    return handler(request, *args, **kwargs)
  File "/home/miroslav/PycharmProjects/Project_nova_poshta-simulator/nova_poshta/main/views.py", line 26, in get
    print(vehicle['max_weight'])
TypeError: 'NoneType' object is not subscriptable
Internal Server Error: /np/
Traceback (most recent call last):
  File "/home/miroslav/PycharmProjects/Project_nova_poshta-simulator/venv/lib/python3.6/site-packages/django/core/handlers/exception.py", line 35, in inner
    response = get_response(request)
  File "/home/miroslav/PycharmProjects/Project_nova_poshta-simulator/venv/lib/python3.6/site-packages/django/core/handlers/base.py", line 128, in _get_response
    response = self.process_exception_by_middleware(e, request)
  File "/home/miroslav/PycharmProjects/Project_nova_poshta-simulator/venv/lib/python3.6/site-packages/django/core/handlers/base.py", line 126, in _get_response
    response = wrapped_callback(request, *callback_args, **callback_kwargs)
  File "/home/miroslav/PycharmProjects/Project_nova_poshta-simulator/venv/lib/python3.6/site-packages/django/views/generic/base.py", line 69, in view
    return self.dispatch(request, *args, **kwargs)
  File "/home/miroslav/PycharmProjects/Project_nova_poshta-simulator/venv/lib/python3.6/site-packages/django/views/generic/base.py", line 89, in dispatch
    return handler(request, *args, **kwargs)
  File "/home/miroslav/PycharmProjects/Project_nova_poshta-simulator/nova_poshta/main/views.py", line 26, in get
    print(vehicle['max_weight'])
TypeError: 'NoneType' object is not subscriptable
Internal Server Error: /np/
Traceback (most recent call last):
  File "/home/miroslav/PycharmProjects/Project_nova_poshta-simulator/venv/lib/python3.6/site-packages/django/core/handlers/exception.py", line 35, in inner
    response = get_response(request)
  File "/home/miroslav/PycharmProjects/Project_nova_poshta-simulator/venv/lib/python3.6/site-packages/django/core/handlers/base.py", line 128, in _get_response
    response = self.process_exception_by_middleware(e, request)
  File "/home/miroslav/PycharmProjects/Project_nova_poshta-simulator/venv/lib/python3.6/site-packages/django/core/handlers/base.py", line 126, in _get_response
    response = wrapped_callback(request, *callback_args, **callback_kwargs)
  File "/home/miroslav/PycharmProjects/Project_nova_poshta-simulator/venv/lib/python3.6/site-packages/django/views/generic/base.py", line 69, in view
    return self.dispatch(request, *args, **kwargs)
  File "/home/miroslav/PycharmProjects/Project_nova_poshta-simulator/venv/lib/python3.6/site-packages/django/views/generic/base.py", line 89, in dispatch
    return handler(request, *args, **kwargs)
  File "/home/miroslav/PycharmProjects/Project_nova_poshta-simulator/nova_poshta/main/views.py", line 26, in get
    print(vehicle.max_weight)
AttributeError: 'NoneType' object has no attribute 'max_weight'
Internal Server Error: /np/
Traceback (most recent call last):
  File "/home/miroslav/PycharmProjects/Project_nova_poshta-simulator/venv/lib/python3.6/site-packages/django/core/handlers/exception.py", line 35, in inner
    response = get_response(request)
  File "/home/miroslav/PycharmProjects/Project_nova_poshta-simulator/venv/lib/python3.6/site-packages/django/core/handlers/base.py", line 128, in _get_response
    response = self.process_exception_by_middleware(e, request)
  File "/home/miroslav/PycharmProjects/Project_nova_poshta-simulator/venv/lib/python3.6/site-packages/django/core/handlers/base.py", line 126, in _get_response
    response = wrapped_callback(request, *callback_args, **callback_kwargs)
  File "/home/miroslav/PycharmProjects/Project_nova_poshta-simulator/venv/lib/python3.6/site-packages/django/views/generic/base.py", line 69, in view
    return self.dispatch(request, *args, **kwargs)
  File "/home/miroslav/PycharmProjects/Project_nova_poshta-simulator/venv/lib/python3.6/site-packages/django/views/generic/base.py", line 89, in dispatch
    return handler(request, *args, **kwargs)
  File "/home/miroslav/PycharmProjects/Project_nova_poshta-simulator/nova_poshta/main/views.py", line 26, in get
    print(vehicle.max_weight)
AttributeError: 'NoneType' object has no attribute 'max_weight'
Internal Server Error: /np/
Traceback (most recent call last):
  File "/home/miroslav/PycharmProjects/Project_nova_poshta-simulator/venv/lib/python3.6/site-packages/django/core/handlers/exception.py", line 35, in inner
    response = get_response(request)
  File "/home/miroslav/PycharmProjects/Project_nova_poshta-simulator/venv/lib/python3.6/site-packages/django/core/handlers/base.py", line 128, in _get_response
    response = self.process_exception_by_middleware(e, request)
  File "/home/miroslav/PycharmProjects/Project_nova_poshta-simulator/venv/lib/python3.6/site-packages/django/core/handlers/base.py", line 126, in _get_response
    response = wrapped_callback(request, *callback_args, **callback_kwargs)
  File "/home/miroslav/PycharmProjects/Project_nova_poshta-simulator/venv/lib/python3.6/site-packages/django/views/generic/base.py", line 69, in view
    return self.dispatch(request, *args, **kwargs)
  File "/home/miroslav/PycharmProjects/Project_nova_poshta-simulator/venv/lib/python3.6/site-packages/django/views/generic/base.py", line 89, in dispatch
    return handler(request, *args, **kwargs)
  File "/home/miroslav/PycharmProjects/Project_nova_poshta-simulator/nova_poshta/main/views.py", line 27, in get
    Vehicle.objects.first().update(max_weight=Vehicle.objects.first().max_weight - 100)
AttributeError: 'Vehicle' object has no attribute 'update'
Internal Server Error: /np/
Traceback (most recent call last):
  File "/home/miroslav/PycharmProjects/Project_nova_poshta-simulator/venv/lib/python3.6/site-packages/django/core/handlers/exception.py", line 35, in inner
    response = get_response(request)
  File "/home/miroslav/PycharmProjects/Project_nova_poshta-simulator/venv/lib/python3.6/site-packages/django/core/handlers/base.py", line 128, in _get_response
    response = self.process_exception_by_middleware(e, request)
  File "/home/miroslav/PycharmProjects/Project_nova_poshta-simulator/venv/lib/python3.6/site-packages/django/core/handlers/base.py", line 126, in _get_response
    response = wrapped_callback(request, *callback_args, **callback_kwargs)
  File "/home/miroslav/PycharmProjects/Project_nova_poshta-simulator/venv/lib/python3.6/site-packages/django/views/generic/base.py", line 69, in view
    return self.dispatch(request, *args, **kwargs)
  File "/home/miroslav/PycharmProjects/Project_nova_poshta-simulator/venv/lib/python3.6/site-packages/django/views/generic/base.py", line 89, in dispatch
    return handler(request, *args, **kwargs)
  File "/home/miroslav/PycharmProjects/Project_nova_poshta-simulator/nova_poshta/main/views.py", line 27, in get
    Vehicle.objects.filter(name=vehicle.name).update(max_weight=Vehicle.objects.first().max_weight - 100)
AttributeError: 'int' object has no attribute 'name'
Internal Server Error: /np/
Traceback (most recent call last):
  File "/home/miroslav/PycharmProjects/Project_nova_poshta-simulator/venv/lib/python3.6/site-packages/django/core/handlers/exception.py", line 35, in inner
    response = get_response(request)
  File "/home/miroslav/PycharmProjects/Project_nova_poshta-simulator/venv/lib/python3.6/site-packages/django/core/handlers/base.py", line 128, in _get_response
    response = self.process_exception_by_middleware(e, request)
  File "/home/miroslav/PycharmProjects/Project_nova_poshta-simulator/venv/lib/python3.6/site-packages/django/core/handlers/base.py", line 126, in _get_response
    response = wrapped_callback(request, *callback_args, **callback_kwargs)
  File "/home/miroslav/PycharmProjects/Project_nova_poshta-simulator/venv/lib/python3.6/site-packages/django/views/generic/base.py", line 69, in view
    return self.dispatch(request, *args, **kwargs)
  File "/home/miroslav/PycharmProjects/Project_nova_poshta-simulator/venv/lib/python3.6/site-packages/django/views/generic/base.py", line 89, in dispatch
    return handler(request, *args, **kwargs)
  File "/home/miroslav/PycharmProjects/Project_nova_poshta-simulator/nova_poshta/main/views.py", line 27, in get
    Vehicle.objects.filter(name=vehicle.name).update(max_weight=Vehicle.objects.first().max_weight - 100)
AttributeError: 'int' object has no attribute 'name'
Not Found: /favicon.ico
Not Found: /favicon.ico
Internal Server Error: /np/
Traceback (most recent call last):
  File "/home/miroslav/PycharmProjects/Project_nova_poshta-simulator/venv/lib/python3.6/site-packages/django/core/handlers/exception.py", line 35, in inner
    response = get_response(request)
  File "/home/miroslav/PycharmProjects/Project_nova_poshta-simulator/venv/lib/python3.6/site-packages/django/core/handlers/base.py", line 128, in _get_response
    response = self.process_exception_by_middleware(e, request)
  File "/home/miroslav/PycharmProjects/Project_nova_poshta-simulator/venv/lib/python3.6/site-packages/django/core/handlers/base.py", line 126, in _get_response
    response = wrapped_callback(request, *callback_args, **callback_kwargs)
  File "/home/miroslav/PycharmProjects/Project_nova_poshta-simulator/venv/lib/python3.6/site-packages/django/views/generic/base.py", line 69, in view
    return self.dispatch(request, *args, **kwargs)
  File "/home/miroslav/PycharmProjects/Project_nova_poshta-simulator/venv/lib/python3.6/site-packages/django/views/generic/base.py", line 89, in dispatch
    return handler(request, *args, **kwargs)
  File "/home/miroslav/PycharmProjects/Project_nova_poshta-simulator/nova_poshta/main/views.py", line 26, in get
    orders_current = Order.objects.filter(sender=request.user, completed=False)
  File "/home/miroslav/PycharmProjects/Project_nova_poshta-simulator/venv/lib/python3.6/site-packages/django/db/models/manager.py", line 82, in manager_method
    return getattr(self.get_queryset(), name)(*args, **kwargs)
  File "/home/miroslav/PycharmProjects/Project_nova_poshta-simulator/venv/lib/python3.6/site-packages/django/db/models/query.py", line 836, in filter
    return self._filter_or_exclude(False, *args, **kwargs)
  File "/home/miroslav/PycharmProjects/Project_nova_poshta-simulator/venv/lib/python3.6/site-packages/django/db/models/query.py", line 854, in _filter_or_exclude
    clone.query.add_q(Q(*args, **kwargs))
  File "/home/miroslav/PycharmProjects/Project_nova_poshta-simulator/venv/lib/python3.6/site-packages/django/db/models/sql/query.py", line 1253, in add_q
    clause, _ = self._add_q(q_object, self.used_aliases)
  File "/home/miroslav/PycharmProjects/Project_nova_poshta-simulator/venv/lib/python3.6/site-packages/django/db/models/sql/query.py", line 1277, in _add_q
    split_subq=split_subq,
  File "/home/miroslav/PycharmProjects/Project_nova_poshta-simulator/venv/lib/python3.6/site-packages/django/db/models/sql/query.py", line 1153, in build_filter
    lookups, parts, reffed_expression = self.solve_lookup_type(arg)
  File "/home/miroslav/PycharmProjects/Project_nova_poshta-simulator/venv/lib/python3.6/site-packages/django/db/models/sql/query.py", line 1015, in solve_lookup_type
    _, field, _, lookup_parts = self.names_to_path(lookup_splitted, self.get_meta())
  File "/home/miroslav/PycharmProjects/Project_nova_poshta-simulator/venv/lib/python3.6/site-packages/django/db/models/sql/query.py", line 1379, in names_to_path
    "Choices are: %s" % (name, ", ".join(available)))
django.core.exceptions.FieldError: Cannot resolve keyword 'completed' into field. Choices are: getter_email, getter_name, getter_surname, id, order_name, punkt_from, punkt_from_id, punkt_to, punkt_to_id, sender, sender_id, status, vehicle, vehicle_id, weight
Internal Server Error: /np/
Traceback (most recent call last):
  File "/home/miroslav/PycharmProjects/Project_nova_poshta-simulator/venv/lib/python3.6/site-packages/django/core/handlers/exception.py", line 35, in inner
    response = get_response(request)
  File "/home/miroslav/PycharmProjects/Project_nova_poshta-simulator/venv/lib/python3.6/site-packages/django/core/handlers/base.py", line 128, in _get_response
    response = self.process_exception_by_middleware(e, request)
  File "/home/miroslav/PycharmProjects/Project_nova_poshta-simulator/venv/lib/python3.6/site-packages/django/core/handlers/base.py", line 126, in _get_response
    response = wrapped_callback(request, *callback_args, **callback_kwargs)
  File "/home/miroslav/PycharmProjects/Project_nova_poshta-simulator/venv/lib/python3.6/site-packages/django/views/generic/base.py", line 69, in view
    return self.dispatch(request, *args, **kwargs)
  File "/home/miroslav/PycharmProjects/Project_nova_poshta-simulator/venv/lib/python3.6/site-packages/django/views/generic/base.py", line 89, in dispatch
    return handler(request, *args, **kwargs)
  File "/home/miroslav/PycharmProjects/Project_nova_poshta-simulator/nova_poshta/main/views.py", line 26, in get
    orders_current = Order.objects.filter(sender=request.user, completed=False)
  File "/home/miroslav/PycharmProjects/Project_nova_poshta-simulator/venv/lib/python3.6/site-packages/django/db/models/manager.py", line 82, in manager_method
    return getattr(self.get_queryset(), name)(*args, **kwargs)
  File "/home/miroslav/PycharmProjects/Project_nova_poshta-simulator/venv/lib/python3.6/site-packages/django/db/models/query.py", line 836, in filter
    return self._filter_or_exclude(False, *args, **kwargs)
  File "/home/miroslav/PycharmProjects/Project_nova_poshta-simulator/venv/lib/python3.6/site-packages/django/db/models/query.py", line 854, in _filter_or_exclude
    clone.query.add_q(Q(*args, **kwargs))
  File "/home/miroslav/PycharmProjects/Project_nova_poshta-simulator/venv/lib/python3.6/site-packages/django/db/models/sql/query.py", line 1253, in add_q
    clause, _ = self._add_q(q_object, self.used_aliases)
  File "/home/miroslav/PycharmProjects/Project_nova_poshta-simulator/venv/lib/python3.6/site-packages/django/db/models/sql/query.py", line 1277, in _add_q
    split_subq=split_subq,
  File "/home/miroslav/PycharmProjects/Project_nova_poshta-simulator/venv/lib/python3.6/site-packages/django/db/models/sql/query.py", line 1153, in build_filter
    lookups, parts, reffed_expression = self.solve_lookup_type(arg)
  File "/home/miroslav/PycharmProjects/Project_nova_poshta-simulator/venv/lib/python3.6/site-packages/django/db/models/sql/query.py", line 1015, in solve_lookup_type
    _, field, _, lookup_parts = self.names_to_path(lookup_splitted, self.get_meta())
  File "/home/miroslav/PycharmProjects/Project_nova_poshta-simulator/venv/lib/python3.6/site-packages/django/db/models/sql/query.py", line 1379, in names_to_path
    "Choices are: %s" % (name, ", ".join(available)))
django.core.exceptions.FieldError: Cannot resolve keyword 'completed' into field. Choices are: getter_email, getter_name, getter_surname, id, order_name, punkt_from, punkt_from_id, punkt_to, punkt_to_id, sender, sender_id, status, vehicle, vehicle_id, weight
Internal Server Error: /np/
Traceback (most recent call last):
  File "/home/miroslav/PycharmProjects/Project_nova_poshta-simulator/venv/lib/python3.6/site-packages/django/core/handlers/exception.py", line 35, in inner
    response = get_response(request)
  File "/home/miroslav/PycharmProjects/Project_nova_poshta-simulator/venv/lib/python3.6/site-packages/django/core/handlers/base.py", line 128, in _get_response
    response = self.process_exception_by_middleware(e, request)
  File "/home/miroslav/PycharmProjects/Project_nova_poshta-simulator/venv/lib/python3.6/site-packages/django/core/handlers/base.py", line 126, in _get_response
    response = wrapped_callback(request, *callback_args, **callback_kwargs)
  File "/home/miroslav/PycharmProjects/Project_nova_poshta-simulator/venv/lib/python3.6/site-packages/django/views/generic/base.py", line 69, in view
    return self.dispatch(request, *args, **kwargs)
  File "/home/miroslav/PycharmProjects/Project_nova_poshta-simulator/venv/lib/python3.6/site-packages/django/views/generic/base.py", line 89, in dispatch
    return handler(request, *args, **kwargs)
  File "/home/miroslav/PycharmProjects/Project_nova_poshta-simulator/nova_poshta/main/views.py", line 26, in get
    orders_current = Order.objects.filter(sender=request.user, completed=False)
  File "/home/miroslav/PycharmProjects/Project_nova_poshta-simulator/venv/lib/python3.6/site-packages/django/db/models/manager.py", line 82, in manager_method
    return getattr(self.get_queryset(), name)(*args, **kwargs)
  File "/home/miroslav/PycharmProjects/Project_nova_poshta-simulator/venv/lib/python3.6/site-packages/django/db/models/query.py", line 836, in filter
    return self._filter_or_exclude(False, *args, **kwargs)
  File "/home/miroslav/PycharmProjects/Project_nova_poshta-simulator/venv/lib/python3.6/site-packages/django/db/models/query.py", line 854, in _filter_or_exclude
    clone.query.add_q(Q(*args, **kwargs))
  File "/home/miroslav/PycharmProjects/Project_nova_poshta-simulator/venv/lib/python3.6/site-packages/django/db/models/sql/query.py", line 1253, in add_q
    clause, _ = self._add_q(q_object, self.used_aliases)
  File "/home/miroslav/PycharmProjects/Project_nova_poshta-simulator/venv/lib/python3.6/site-packages/django/db/models/sql/query.py", line 1277, in _add_q
    split_subq=split_subq,
  File "/home/miroslav/PycharmProjects/Project_nova_poshta-simulator/venv/lib/python3.6/site-packages/django/db/models/sql/query.py", line 1153, in build_filter
    lookups, parts, reffed_expression = self.solve_lookup_type(arg)
  File "/home/miroslav/PycharmProjects/Project_nova_poshta-simulator/venv/lib/python3.6/site-packages/django/db/models/sql/query.py", line 1015, in solve_lookup_type
    _, field, _, lookup_parts = self.names_to_path(lookup_splitted, self.get_meta())
  File "/home/miroslav/PycharmProjects/Project_nova_poshta-simulator/venv/lib/python3.6/site-packages/django/db/models/sql/query.py", line 1379, in names_to_path
    "Choices are: %s" % (name, ", ".join(available)))
django.core.exceptions.FieldError: Cannot resolve keyword 'completed' into field. Choices are: getter_email, getter_name, getter_surname, id, order_name, punkt_from, punkt_from_id, punkt_to, punkt_to_id, sender, sender_id, status, vehicle, vehicle_id, weight
Internal Server Error: /np/
Traceback (most recent call last):
  File "/home/miroslav/PycharmProjects/Project_nova_poshta-simulator/venv/lib/python3.6/site-packages/django/core/handlers/exception.py", line 35, in inner
    response = get_response(request)
  File "/home/miroslav/PycharmProjects/Project_nova_poshta-simulator/venv/lib/python3.6/site-packages/django/core/handlers/base.py", line 128, in _get_response
    response = self.process_exception_by_middleware(e, request)
  File "/home/miroslav/PycharmProjects/Project_nova_poshta-simulator/venv/lib/python3.6/site-packages/django/core/handlers/base.py", line 126, in _get_response
    response = wrapped_callback(request, *callback_args, **callback_kwargs)
  File "/home/miroslav/PycharmProjects/Project_nova_poshta-simulator/venv/lib/python3.6/site-packages/django/views/generic/base.py", line 69, in view
    return self.dispatch(request, *args, **kwargs)
  File "/home/miroslav/PycharmProjects/Project_nova_poshta-simulator/venv/lib/python3.6/site-packages/django/views/generic/base.py", line 89, in dispatch
    return handler(request, *args, **kwargs)
  File "/home/miroslav/PycharmProjects/Project_nova_poshta-simulator/nova_poshta/main/views.py", line 26, in get
    orders_current = Order.objects.filter(sender=request.user, completed=False)
  File "/home/miroslav/PycharmProjects/Project_nova_poshta-simulator/venv/lib/python3.6/site-packages/django/db/models/manager.py", line 82, in manager_method
    return getattr(self.get_queryset(), name)(*args, **kwargs)
  File "/home/miroslav/PycharmProjects/Project_nova_poshta-simulator/venv/lib/python3.6/site-packages/django/db/models/query.py", line 836, in filter
    return self._filter_or_exclude(False, *args, **kwargs)
  File "/home/miroslav/PycharmProjects/Project_nova_poshta-simulator/venv/lib/python3.6/site-packages/django/db/models/query.py", line 854, in _filter_or_exclude
    clone.query.add_q(Q(*args, **kwargs))
  File "/home/miroslav/PycharmProjects/Project_nova_poshta-simulator/venv/lib/python3.6/site-packages/django/db/models/sql/query.py", line 1253, in add_q
    clause, _ = self._add_q(q_object, self.used_aliases)
  File "/home/miroslav/PycharmProjects/Project_nova_poshta-simulator/venv/lib/python3.6/site-packages/django/db/models/sql/query.py", line 1277, in _add_q
    split_subq=split_subq,
  File "/home/miroslav/PycharmProjects/Project_nova_poshta-simulator/venv/lib/python3.6/site-packages/django/db/models/sql/query.py", line 1153, in build_filter
    lookups, parts, reffed_expression = self.solve_lookup_type(arg)
  File "/home/miroslav/PycharmProjects/Project_nova_poshta-simulator/venv/lib/python3.6/site-packages/django/db/models/sql/query.py", line 1015, in solve_lookup_type
    _, field, _, lookup_parts = self.names_to_path(lookup_splitted, self.get_meta())
  File "/home/miroslav/PycharmProjects/Project_nova_poshta-simulator/venv/lib/python3.6/site-packages/django/db/models/sql/query.py", line 1379, in names_to_path
    "Choices are: %s" % (name, ", ".join(available)))
django.core.exceptions.FieldError: Cannot resolve keyword 'completed' into field. Choices are: getter_email, getter_name, getter_surname, id, order_name, punkt_from, punkt_from_id, punkt_to, punkt_to_id, sender, sender_id, status, vehicle, vehicle_id, weight
Internal Server Error: /np/
Traceback (most recent call last):
  File "/home/miroslav/PycharmProjects/Project_nova_poshta-simulator/venv/lib/python3.6/site-packages/django/core/handlers/exception.py", line 35, in inner
    response = get_response(request)
  File "/home/miroslav/PycharmProjects/Project_nova_poshta-simulator/venv/lib/python3.6/site-packages/django/core/handlers/base.py", line 128, in _get_response
    response = self.process_exception_by_middleware(e, request)
  File "/home/miroslav/PycharmProjects/Project_nova_poshta-simulator/venv/lib/python3.6/site-packages/django/core/handlers/base.py", line 126, in _get_response
    response = wrapped_callback(request, *callback_args, **callback_kwargs)
  File "/home/miroslav/PycharmProjects/Project_nova_poshta-simulator/venv/lib/python3.6/site-packages/django/views/generic/base.py", line 69, in view
    return self.dispatch(request, *args, **kwargs)
  File "/home/miroslav/PycharmProjects/Project_nova_poshta-simulator/venv/lib/python3.6/site-packages/django/views/generic/base.py", line 89, in dispatch
    return handler(request, *args, **kwargs)
  File "/home/miroslav/PycharmProjects/Project_nova_poshta-simulator/nova_poshta/main/views.py", line 26, in get
    orders_current = Order.objects.filter(sender=request.user, completed=False)
  File "/home/miroslav/PycharmProjects/Project_nova_poshta-simulator/venv/lib/python3.6/site-packages/django/db/models/manager.py", line 82, in manager_method
    return getattr(self.get_queryset(), name)(*args, **kwargs)
  File "/home/miroslav/PycharmProjects/Project_nova_poshta-simulator/venv/lib/python3.6/site-packages/django/db/models/query.py", line 836, in filter
    return self._filter_or_exclude(False, *args, **kwargs)
  File "/home/miroslav/PycharmProjects/Project_nova_poshta-simulator/venv/lib/python3.6/site-packages/django/db/models/query.py", line 854, in _filter_or_exclude
    clone.query.add_q(Q(*args, **kwargs))
  File "/home/miroslav/PycharmProjects/Project_nova_poshta-simulator/venv/lib/python3.6/site-packages/django/db/models/sql/query.py", line 1253, in add_q
    clause, _ = self._add_q(q_object, self.used_aliases)
  File "/home/miroslav/PycharmProjects/Project_nova_poshta-simulator/venv/lib/python3.6/site-packages/django/db/models/sql/query.py", line 1277, in _add_q
    split_subq=split_subq,
  File "/home/miroslav/PycharmProjects/Project_nova_poshta-simulator/venv/lib/python3.6/site-packages/django/db/models/sql/query.py", line 1153, in build_filter
    lookups, parts, reffed_expression = self.solve_lookup_type(arg)
  File "/home/miroslav/PycharmProjects/Project_nova_poshta-simulator/venv/lib/python3.6/site-packages/django/db/models/sql/query.py", line 1015, in solve_lookup_type
    _, field, _, lookup_parts = self.names_to_path(lookup_splitted, self.get_meta())
  File "/home/miroslav/PycharmProjects/Project_nova_poshta-simulator/venv/lib/python3.6/site-packages/django/db/models/sql/query.py", line 1379, in names_to_path
    "Choices are: %s" % (name, ", ".join(available)))
django.core.exceptions.FieldError: Cannot resolve keyword 'completed' into field. Choices are: getter_email, getter_name, getter_surname, id, order_name, punkt_from, punkt_from_id, punkt_to, punkt_to_id, sender, sender_id, status, vehicle, vehicle_id, weight
Internal Server Error: /np/
Traceback (most recent call last):
  File "/home/miroslav/PycharmProjects/Project_nova_poshta-simulator/venv/lib/python3.6/site-packages/django/core/handlers/exception.py", line 35, in inner
    response = get_response(request)
  File "/home/miroslav/PycharmProjects/Project_nova_poshta-simulator/venv/lib/python3.6/site-packages/django/core/handlers/base.py", line 128, in _get_response
    response = self.process_exception_by_middleware(e, request)
  File "/home/miroslav/PycharmProjects/Project_nova_poshta-simulator/venv/lib/python3.6/site-packages/django/core/handlers/base.py", line 126, in _get_response
    response = wrapped_callback(request, *callback_args, **callback_kwargs)
  File "/home/miroslav/PycharmProjects/Project_nova_poshta-simulator/venv/lib/python3.6/site-packages/django/views/generic/base.py", line 69, in view
    return self.dispatch(request, *args, **kwargs)
  File "/home/miroslav/PycharmProjects/Project_nova_poshta-simulator/venv/lib/python3.6/site-packages/django/views/generic/base.py", line 89, in dispatch
    return handler(request, *args, **kwargs)
  File "/home/miroslav/PycharmProjects/Project_nova_poshta-simulator/nova_poshta/main/views.py", line 26, in get
    orders_current = Order.objects.filter(sender=request.user, completed=False)
  File "/home/miroslav/PycharmProjects/Project_nova_poshta-simulator/venv/lib/python3.6/site-packages/django/db/models/manager.py", line 82, in manager_method
    return getattr(self.get_queryset(), name)(*args, **kwargs)
  File "/home/miroslav/PycharmProjects/Project_nova_poshta-simulator/venv/lib/python3.6/site-packages/django/db/models/query.py", line 836, in filter
    return self._filter_or_exclude(False, *args, **kwargs)
  File "/home/miroslav/PycharmProjects/Project_nova_poshta-simulator/venv/lib/python3.6/site-packages/django/db/models/query.py", line 854, in _filter_or_exclude
    clone.query.add_q(Q(*args, **kwargs))
  File "/home/miroslav/PycharmProjects/Project_nova_poshta-simulator/venv/lib/python3.6/site-packages/django/db/models/sql/query.py", line 1253, in add_q
    clause, _ = self._add_q(q_object, self.used_aliases)
  File "/home/miroslav/PycharmProjects/Project_nova_poshta-simulator/venv/lib/python3.6/site-packages/django/db/models/sql/query.py", line 1277, in _add_q
    split_subq=split_subq,
  File "/home/miroslav/PycharmProjects/Project_nova_poshta-simulator/venv/lib/python3.6/site-packages/django/db/models/sql/query.py", line 1153, in build_filter
    lookups, parts, reffed_expression = self.solve_lookup_type(arg)
  File "/home/miroslav/PycharmProjects/Project_nova_poshta-simulator/venv/lib/python3.6/site-packages/django/db/models/sql/query.py", line 1015, in solve_lookup_type
    _, field, _, lookup_parts = self.names_to_path(lookup_splitted, self.get_meta())
  File "/home/miroslav/PycharmProjects/Project_nova_poshta-simulator/venv/lib/python3.6/site-packages/django/db/models/sql/query.py", line 1379, in names_to_path
    "Choices are: %s" % (name, ", ".join(available)))
django.core.exceptions.FieldError: Cannot resolve keyword 'completed' into field. Choices are: getter_email, getter_name, getter_surname, id, order_name, punkt_from, punkt_from_id, punkt_to, punkt_to_id, sender, sender_id, status, vehicle, vehicle_id, weight
Internal Server Error: /np/
Traceback (most recent call last):
  File "/home/miroslav/PycharmProjects/Project_nova_poshta-simulator/venv/lib/python3.6/site-packages/django/core/handlers/exception.py", line 35, in inner
    response = get_response(request)
  File "/home/miroslav/PycharmProjects/Project_nova_poshta-simulator/venv/lib/python3.6/site-packages/django/core/handlers/base.py", line 128, in _get_response
    response = self.process_exception_by_middleware(e, request)
  File "/home/miroslav/PycharmProjects/Project_nova_poshta-simulator/venv/lib/python3.6/site-packages/django/core/handlers/base.py", line 126, in _get_response
    response = wrapped_callback(request, *callback_args, **callback_kwargs)
  File "/home/miroslav/PycharmProjects/Project_nova_poshta-simulator/venv/lib/python3.6/site-packages/django/views/generic/base.py", line 69, in view
    return self.dispatch(request, *args, **kwargs)
  File "/home/miroslav/PycharmProjects/Project_nova_poshta-simulator/venv/lib/python3.6/site-packages/django/views/generic/base.py", line 89, in dispatch
    return handler(request, *args, **kwargs)
  File "/home/miroslav/PycharmProjects/Project_nova_poshta-simulator/nova_poshta/main/views.py", line 28, in get
    orders_waiting = Order.objects.filter(sender=request.user, status_gte=Order.STATUS_WAITING)
  File "/home/miroslav/PycharmProjects/Project_nova_poshta-simulator/venv/lib/python3.6/site-packages/django/db/models/manager.py", line 82, in manager_method
    return getattr(self.get_queryset(), name)(*args, **kwargs)
  File "/home/miroslav/PycharmProjects/Project_nova_poshta-simulator/venv/lib/python3.6/site-packages/django/db/models/query.py", line 836, in filter
    return self._filter_or_exclude(False, *args, **kwargs)
  File "/home/miroslav/PycharmProjects/Project_nova_poshta-simulator/venv/lib/python3.6/site-packages/django/db/models/query.py", line 854, in _filter_or_exclude
    clone.query.add_q(Q(*args, **kwargs))
  File "/home/miroslav/PycharmProjects/Project_nova_poshta-simulator/venv/lib/python3.6/site-packages/django/db/models/sql/query.py", line 1253, in add_q
    clause, _ = self._add_q(q_object, self.used_aliases)
  File "/home/miroslav/PycharmProjects/Project_nova_poshta-simulator/venv/lib/python3.6/site-packages/django/db/models/sql/query.py", line 1277, in _add_q
    split_subq=split_subq,
  File "/home/miroslav/PycharmProjects/Project_nova_poshta-simulator/venv/lib/python3.6/site-packages/django/db/models/sql/query.py", line 1153, in build_filter
    lookups, parts, reffed_expression = self.solve_lookup_type(arg)
  File "/home/miroslav/PycharmProjects/Project_nova_poshta-simulator/venv/lib/python3.6/site-packages/django/db/models/sql/query.py", line 1015, in solve_lookup_type
    _, field, _, lookup_parts = self.names_to_path(lookup_splitted, self.get_meta())
  File "/home/miroslav/PycharmProjects/Project_nova_poshta-simulator/venv/lib/python3.6/site-packages/django/db/models/sql/query.py", line 1379, in names_to_path
    "Choices are: %s" % (name, ", ".join(available)))
django.core.exceptions.FieldError: Cannot resolve keyword 'status_gte' into field. Choices are: getter_email, getter_name, getter_surname, id, order_name, punkt_from, punkt_from_id, punkt_to, punkt_to_id, sender, sender_id, status, vehicle, vehicle_id, weight
Internal Server Error: /np/
Traceback (most recent call last):
  File "/home/miroslav/PycharmProjects/Project_nova_poshta-simulator/venv/lib/python3.6/site-packages/django/core/handlers/exception.py", line 35, in inner
    response = get_response(request)
  File "/home/miroslav/PycharmProjects/Project_nova_poshta-simulator/venv/lib/python3.6/site-packages/django/core/handlers/base.py", line 128, in _get_response
    response = self.process_exception_by_middleware(e, request)
  File "/home/miroslav/PycharmProjects/Project_nova_poshta-simulator/venv/lib/python3.6/site-packages/django/core/handlers/base.py", line 126, in _get_response
    response = wrapped_callback(request, *callback_args, **callback_kwargs)
  File "/home/miroslav/PycharmProjects/Project_nova_poshta-simulator/venv/lib/python3.6/site-packages/django/views/generic/base.py", line 69, in view
    return self.dispatch(request, *args, **kwargs)
  File "/home/miroslav/PycharmProjects/Project_nova_poshta-simulator/venv/lib/python3.6/site-packages/django/views/generic/base.py", line 89, in dispatch
    return handler(request, *args, **kwargs)
  File "/home/miroslav/PycharmProjects/Project_nova_poshta-simulator/nova_poshta/main/views.py", line 28, in get
    orders_waiting = Order.objects.filter(sender=request.user, status_gte=Order.STATUS_WAITING)
  File "/home/miroslav/PycharmProjects/Project_nova_poshta-simulator/venv/lib/python3.6/site-packages/django/db/models/manager.py", line 82, in manager_method
    return getattr(self.get_queryset(), name)(*args, **kwargs)
  File "/home/miroslav/PycharmProjects/Project_nova_poshta-simulator/venv/lib/python3.6/site-packages/django/db/models/query.py", line 836, in filter
    return self._filter_or_exclude(False, *args, **kwargs)
  File "/home/miroslav/PycharmProjects/Project_nova_poshta-simulator/venv/lib/python3.6/site-packages/django/db/models/query.py", line 854, in _filter_or_exclude
    clone.query.add_q(Q(*args, **kwargs))
  File "/home/miroslav/PycharmProjects/Project_nova_poshta-simulator/venv/lib/python3.6/site-packages/django/db/models/sql/query.py", line 1253, in add_q
    clause, _ = self._add_q(q_object, self.used_aliases)
  File "/home/miroslav/PycharmProjects/Project_nova_poshta-simulator/venv/lib/python3.6/site-packages/django/db/models/sql/query.py", line 1277, in _add_q
    split_subq=split_subq,
  File "/home/miroslav/PycharmProjects/Project_nova_poshta-simulator/venv/lib/python3.6/site-packages/django/db/models/sql/query.py", line 1153, in build_filter
    lookups, parts, reffed_expression = self.solve_lookup_type(arg)
  File "/home/miroslav/PycharmProjects/Project_nova_poshta-simulator/venv/lib/python3.6/site-packages/django/db/models/sql/query.py", line 1015, in solve_lookup_type
    _, field, _, lookup_parts = self.names_to_path(lookup_splitted, self.get_meta())
  File "/home/miroslav/PycharmProjects/Project_nova_poshta-simulator/venv/lib/python3.6/site-packages/django/db/models/sql/query.py", line 1379, in names_to_path
    "Choices are: %s" % (name, ", ".join(available)))
django.core.exceptions.FieldError: Cannot resolve keyword 'status_gte' into field. Choices are: getter_email, getter_name, getter_surname, id, order_name, punkt_from, punkt_from_id, punkt_to, punkt_to_id, sender, sender_id, status, vehicle, vehicle_id, weight
Internal Server Error: /np/add_order
Traceback (most recent call last):
  File "/home/miroslav/PycharmProjects/Project_nova_poshta-simulator/venv/lib/python3.6/site-packages/django/core/handlers/exception.py", line 35, in inner
    response = get_response(request)
  File "/home/miroslav/PycharmProjects/Project_nova_poshta-simulator/venv/lib/python3.6/site-packages/django/core/handlers/base.py", line 128, in _get_response
    response = self.process_exception_by_middleware(e, request)
  File "/home/miroslav/PycharmProjects/Project_nova_poshta-simulator/venv/lib/python3.6/site-packages/django/core/handlers/base.py", line 126, in _get_response
    response = wrapped_callback(request, *callback_args, **callback_kwargs)
  File "/home/miroslav/PycharmProjects/Project_nova_poshta-simulator/venv/lib/python3.6/site-packages/django/views/generic/base.py", line 69, in view
    return self.dispatch(request, *args, **kwargs)
  File "/home/miroslav/PycharmProjects/Project_nova_poshta-simulator/venv/lib/python3.6/site-packages/django/views/generic/base.py", line 89, in dispatch
    return handler(request, *args, **kwargs)
  File "/home/miroslav/PycharmProjects/Project_nova_poshta-simulator/nova_poshta/main/views.py", line 48, in get
    orders_waiting = Order.objects.filter(sender=request.user, status_gte=Order.STATUS_WAITING)
  File "/home/miroslav/PycharmProjects/Project_nova_poshta-simulator/venv/lib/python3.6/site-packages/django/db/models/manager.py", line 82, in manager_method
    return getattr(self.get_queryset(), name)(*args, **kwargs)
  File "/home/miroslav/PycharmProjects/Project_nova_poshta-simulator/venv/lib/python3.6/site-packages/django/db/models/query.py", line 836, in filter
    return self._filter_or_exclude(False, *args, **kwargs)
  File "/home/miroslav/PycharmProjects/Project_nova_poshta-simulator/venv/lib/python3.6/site-packages/django/db/models/query.py", line 854, in _filter_or_exclude
    clone.query.add_q(Q(*args, **kwargs))
  File "/home/miroslav/PycharmProjects/Project_nova_poshta-simulator/venv/lib/python3.6/site-packages/django/db/models/sql/query.py", line 1253, in add_q
    clause, _ = self._add_q(q_object, self.used_aliases)
  File "/home/miroslav/PycharmProjects/Project_nova_poshta-simulator/venv/lib/python3.6/site-packages/django/db/models/sql/query.py", line 1277, in _add_q
    split_subq=split_subq,
  File "/home/miroslav/PycharmProjects/Project_nova_poshta-simulator/venv/lib/python3.6/site-packages/django/db/models/sql/query.py", line 1153, in build_filter
    lookups, parts, reffed_expression = self.solve_lookup_type(arg)
  File "/home/miroslav/PycharmProjects/Project_nova_poshta-simulator/venv/lib/python3.6/site-packages/django/db/models/sql/query.py", line 1015, in solve_lookup_type
    _, field, _, lookup_parts = self.names_to_path(lookup_splitted, self.get_meta())
  File "/home/miroslav/PycharmProjects/Project_nova_poshta-simulator/venv/lib/python3.6/site-packages/django/db/models/sql/query.py", line 1379, in names_to_path
    "Choices are: %s" % (name, ", ".join(available)))
django.core.exceptions.FieldError: Cannot resolve keyword 'status_gte' into field. Choices are: getter_email, getter_name, getter_surname, id, order_name, punkt_from, punkt_from_id, punkt_to, punkt_to_id, sender, sender_id, status, vehicle, vehicle_id, weight
Internal Server Error: /np/add_order
Traceback (most recent call last):
  File "/home/miroslav/PycharmProjects/Project_nova_poshta-simulator/venv/lib/python3.6/site-packages/django/db/backends/utils.py", line 85, in _execute
    return self.cursor.execute(sql, params)
  File "/home/miroslav/PycharmProjects/Project_nova_poshta-simulator/venv/lib/python3.6/site-packages/django/db/backends/sqlite3/base.py", line 303, in execute
    return Database.Cursor.execute(self, query, params)
sqlite3.IntegrityError: NOT NULL constraint failed: main_order.vehicle_id

The above exception was the direct cause of the following exception:

Traceback (most recent call last):
  File "/home/miroslav/PycharmProjects/Project_nova_poshta-simulator/venv/lib/python3.6/site-packages/django/core/handlers/exception.py", line 35, in inner
    response = get_response(request)
  File "/home/miroslav/PycharmProjects/Project_nova_poshta-simulator/venv/lib/python3.6/site-packages/django/core/handlers/base.py", line 128, in _get_response
    response = self.process_exception_by_middleware(e, request)
  File "/home/miroslav/PycharmProjects/Project_nova_poshta-simulator/venv/lib/python3.6/site-packages/django/core/handlers/base.py", line 126, in _get_response
    response = wrapped_callback(request, *callback_args, **callback_kwargs)
  File "/home/miroslav/PycharmProjects/Project_nova_poshta-simulator/venv/lib/python3.6/site-packages/django/views/generic/base.py", line 69, in view
    return self.dispatch(request, *args, **kwargs)
  File "/home/miroslav/PycharmProjects/Project_nova_poshta-simulator/venv/lib/python3.6/site-packages/django/views/generic/base.py", line 89, in dispatch
    return handler(request, *args, **kwargs)
  File "/home/miroslav/PycharmProjects/Project_nova_poshta-simulator/venv/lib/python3.6/site-packages/django/views/generic/edit.py", line 142, in post
    return self.form_valid(form)
  File "/home/miroslav/PycharmProjects/Project_nova_poshta-simulator/nova_poshta/main/views.py", line 61, in form_valid
    form.save(self.request)
  File "/home/miroslav/PycharmProjects/Project_nova_poshta-simulator/nova_poshta/main/forms.py", line 40, in save
    order.save()
  File "/home/miroslav/PycharmProjects/Project_nova_poshta-simulator/venv/lib/python3.6/site-packages/django/db/models/base.py", line 729, in save
    force_update=force_update, update_fields=update_fields)
  File "/home/miroslav/PycharmProjects/Project_nova_poshta-simulator/venv/lib/python3.6/site-packages/django/db/models/base.py", line 759, in save_base
    updated = self._save_table(raw, cls, force_insert, force_update, using, update_fields)
  File "/home/miroslav/PycharmProjects/Project_nova_poshta-simulator/venv/lib/python3.6/site-packages/django/db/models/base.py", line 842, in _save_table
    result = self._do_insert(cls._base_manager, using, fields, update_pk, raw)
  File "/home/miroslav/PycharmProjects/Project_nova_poshta-simulator/venv/lib/python3.6/site-packages/django/db/models/base.py", line 880, in _do_insert
    using=using, raw=raw)
  File "/home/miroslav/PycharmProjects/Project_nova_poshta-simulator/venv/lib/python3.6/site-packages/django/db/models/manager.py", line 82, in manager_method
    return getattr(self.get_queryset(), name)(*args, **kwargs)
  File "/home/miroslav/PycharmProjects/Project_nova_poshta-simulator/venv/lib/python3.6/site-packages/django/db/models/query.py", line 1125, in _insert
    return query.get_compiler(using=using).execute_sql(return_id)
  File "/home/miroslav/PycharmProjects/Project_nova_poshta-simulator/venv/lib/python3.6/site-packages/django/db/models/sql/compiler.py", line 1285, in execute_sql
    cursor.execute(sql, params)
  File "/home/miroslav/PycharmProjects/Project_nova_poshta-simulator/venv/lib/python3.6/site-packages/django/db/backends/utils.py", line 100, in execute
    return super().execute(sql, params)
  File "/home/miroslav/PycharmProjects/Project_nova_poshta-simulator/venv/lib/python3.6/site-packages/django/db/backends/utils.py", line 68, in execute
    return self._execute_with_wrappers(sql, params, many=False, executor=self._execute)
  File "/home/miroslav/PycharmProjects/Project_nova_poshta-simulator/venv/lib/python3.6/site-packages/django/db/backends/utils.py", line 77, in _execute_with_wrappers
    return executor(sql, params, many, context)
  File "/home/miroslav/PycharmProjects/Project_nova_poshta-simulator/venv/lib/python3.6/site-packages/django/db/backends/utils.py", line 85, in _execute
    return self.cursor.execute(sql, params)
  File "/home/miroslav/PycharmProjects/Project_nova_poshta-simulator/venv/lib/python3.6/site-packages/django/db/utils.py", line 89, in __exit__
    raise dj_exc_value.with_traceback(traceback) from exc_value
  File "/home/miroslav/PycharmProjects/Project_nova_poshta-simulator/venv/lib/python3.6/site-packages/django/db/backends/utils.py", line 85, in _execute
    return self.cursor.execute(sql, params)
  File "/home/miroslav/PycharmProjects/Project_nova_poshta-simulator/venv/lib/python3.6/site-packages/django/db/backends/sqlite3/base.py", line 303, in execute
    return Database.Cursor.execute(self, query, params)
django.db.utils.IntegrityError: NOT NULL constraint failed: main_order.vehicle_id
Internal Server Error: /np/add_order
Traceback (most recent call last):
  File "/home/miroslav/PycharmProjects/Project_nova_poshta-simulator/venv/lib/python3.6/site-packages/django/db/backends/utils.py", line 85, in _execute
    return self.cursor.execute(sql, params)
  File "/home/miroslav/PycharmProjects/Project_nova_poshta-simulator/venv/lib/python3.6/site-packages/django/db/backends/sqlite3/base.py", line 303, in execute
    return Database.Cursor.execute(self, query, params)
sqlite3.IntegrityError: NOT NULL constraint failed: main_order.vehicle_id

The above exception was the direct cause of the following exception:

Traceback (most recent call last):
  File "/home/miroslav/PycharmProjects/Project_nova_poshta-simulator/venv/lib/python3.6/site-packages/django/core/handlers/exception.py", line 35, in inner
    response = get_response(request)
  File "/home/miroslav/PycharmProjects/Project_nova_poshta-simulator/venv/lib/python3.6/site-packages/django/core/handlers/base.py", line 128, in _get_response
    response = self.process_exception_by_middleware(e, request)
  File "/home/miroslav/PycharmProjects/Project_nova_poshta-simulator/venv/lib/python3.6/site-packages/django/core/handlers/base.py", line 126, in _get_response
    response = wrapped_callback(request, *callback_args, **callback_kwargs)
  File "/home/miroslav/PycharmProjects/Project_nova_poshta-simulator/venv/lib/python3.6/site-packages/django/views/generic/base.py", line 69, in view
    return self.dispatch(request, *args, **kwargs)
  File "/home/miroslav/PycharmProjects/Project_nova_poshta-simulator/venv/lib/python3.6/site-packages/django/views/generic/base.py", line 89, in dispatch
    return handler(request, *args, **kwargs)
  File "/home/miroslav/PycharmProjects/Project_nova_poshta-simulator/venv/lib/python3.6/site-packages/django/views/generic/edit.py", line 142, in post
    return self.form_valid(form)
  File "/home/miroslav/PycharmProjects/Project_nova_poshta-simulator/nova_poshta/main/views.py", line 61, in form_valid
    form.save(self.request)
  File "/home/miroslav/PycharmProjects/Project_nova_poshta-simulator/nova_poshta/main/forms.py", line 40, in save
    order.save()
  File "/home/miroslav/PycharmProjects/Project_nova_poshta-simulator/venv/lib/python3.6/site-packages/django/db/models/base.py", line 729, in save
    force_update=force_update, update_fields=update_fields)
  File "/home/miroslav/PycharmProjects/Project_nova_poshta-simulator/venv/lib/python3.6/site-packages/django/db/models/base.py", line 759, in save_base
    updated = self._save_table(raw, cls, force_insert, force_update, using, update_fields)
  File "/home/miroslav/PycharmProjects/Project_nova_poshta-simulator/venv/lib/python3.6/site-packages/django/db/models/base.py", line 842, in _save_table
    result = self._do_insert(cls._base_manager, using, fields, update_pk, raw)
  File "/home/miroslav/PycharmProjects/Project_nova_poshta-simulator/venv/lib/python3.6/site-packages/django/db/models/base.py", line 880, in _do_insert
    using=using, raw=raw)
  File "/home/miroslav/PycharmProjects/Project_nova_poshta-simulator/venv/lib/python3.6/site-packages/django/db/models/manager.py", line 82, in manager_method
    return getattr(self.get_queryset(), name)(*args, **kwargs)
  File "/home/miroslav/PycharmProjects/Project_nova_poshta-simulator/venv/lib/python3.6/site-packages/django/db/models/query.py", line 1125, in _insert
    return query.get_compiler(using=using).execute_sql(return_id)
  File "/home/miroslav/PycharmProjects/Project_nova_poshta-simulator/venv/lib/python3.6/site-packages/django/db/models/sql/compiler.py", line 1285, in execute_sql
    cursor.execute(sql, params)
  File "/home/miroslav/PycharmProjects/Project_nova_poshta-simulator/venv/lib/python3.6/site-packages/django/db/backends/utils.py", line 100, in execute
    return super().execute(sql, params)
  File "/home/miroslav/PycharmProjects/Project_nova_poshta-simulator/venv/lib/python3.6/site-packages/django/db/backends/utils.py", line 68, in execute
    return self._execute_with_wrappers(sql, params, many=False, executor=self._execute)
  File "/home/miroslav/PycharmProjects/Project_nova_poshta-simulator/venv/lib/python3.6/site-packages/django/db/backends/utils.py", line 77, in _execute_with_wrappers
    return executor(sql, params, many, context)
  File "/home/miroslav/PycharmProjects/Project_nova_poshta-simulator/venv/lib/python3.6/site-packages/django/db/backends/utils.py", line 85, in _execute
    return self.cursor.execute(sql, params)
  File "/home/miroslav/PycharmProjects/Project_nova_poshta-simulator/venv/lib/python3.6/site-packages/django/db/utils.py", line 89, in __exit__
    raise dj_exc_value.with_traceback(traceback) from exc_value
  File "/home/miroslav/PycharmProjects/Project_nova_poshta-simulator/venv/lib/python3.6/site-packages/django/db/backends/utils.py", line 85, in _execute
    return self.cursor.execute(sql, params)
  File "/home/miroslav/PycharmProjects/Project_nova_poshta-simulator/venv/lib/python3.6/site-packages/django/db/backends/sqlite3/base.py", line 303, in execute
    return Database.Cursor.execute(self, query, params)
django.db.utils.IntegrityError: NOT NULL constraint failed: main_order.vehicle_id
Internal Server Error: /np/
Traceback (most recent call last):
  File "/home/miroslav/PycharmProjects/Project_nova_poshta-simulator/venv/lib/python3.6/site-packages/django/core/handlers/exception.py", line 35, in inner
    response = get_response(request)
  File "/home/miroslav/PycharmProjects/Project_nova_poshta-simulator/venv/lib/python3.6/site-packages/django/core/handlers/base.py", line 128, in _get_response
    response = self.process_exception_by_middleware(e, request)
  File "/home/miroslav/PycharmProjects/Project_nova_poshta-simulator/venv/lib/python3.6/site-packages/django/core/handlers/base.py", line 126, in _get_response
    response = wrapped_callback(request, *callback_args, **callback_kwargs)
  File "/home/miroslav/PycharmProjects/Project_nova_poshta-simulator/venv/lib/python3.6/site-packages/django/views/generic/base.py", line 69, in view
    return self.dispatch(request, *args, **kwargs)
  File "/home/miroslav/PycharmProjects/Project_nova_poshta-simulator/venv/lib/python3.6/site-packages/django/views/generic/base.py", line 89, in dispatch
    return handler(request, *args, **kwargs)
  File "/home/miroslav/PycharmProjects/Project_nova_poshta-simulator/nova_poshta/main/views.py", line 28, in get
    orders_waiting = Order.objects.filter(sender=request.user, status=Order.STATUS_WAITING)
AttributeError: type object 'Order' has no attribute 'STATUS_WAITING'
Not Found: /
Internal Server Error: /np/add_order
Traceback (most recent call last):
  File "/home/miroslav/PycharmProjects/Project_nova_poshta-simulator/venv/lib/python3.6/site-packages/kombu/serialization.py", line 50, in _reraise_errors
    yield
  File "/home/miroslav/PycharmProjects/Project_nova_poshta-simulator/venv/lib/python3.6/site-packages/kombu/serialization.py", line 221, in dumps
    payload = encoder(data)
  File "/home/miroslav/PycharmProjects/Project_nova_poshta-simulator/venv/lib/python3.6/site-packages/kombu/utils/json.py", line 69, in dumps
    **dict(default_kwargs, **kwargs))
  File "/usr/lib/python3.6/json/__init__.py", line 238, in dumps
    **kw).encode(obj)
  File "/usr/lib/python3.6/json/encoder.py", line 199, in encode
    chunks = self.iterencode(o, _one_shot=True)
  File "/usr/lib/python3.6/json/encoder.py", line 257, in iterencode
    return _iterencode(o, 0)
  File "/home/miroslav/PycharmProjects/Project_nova_poshta-simulator/venv/lib/python3.6/site-packages/kombu/utils/json.py", line 59, in default
    return super(JSONEncoder, self).default(o)
  File "/usr/lib/python3.6/json/encoder.py", line 180, in default
    o.__class__.__name__)
TypeError: Object of type 'User' is not JSON serializable

During handling of the above exception, another exception occurred:

Traceback (most recent call last):
  File "/home/miroslav/PycharmProjects/Project_nova_poshta-simulator/venv/lib/python3.6/site-packages/django/core/handlers/exception.py", line 35, in inner
    response = get_response(request)
  File "/home/miroslav/PycharmProjects/Project_nova_poshta-simulator/venv/lib/python3.6/site-packages/django/core/handlers/base.py", line 128, in _get_response
    response = self.process_exception_by_middleware(e, request)
  File "/home/miroslav/PycharmProjects/Project_nova_poshta-simulator/venv/lib/python3.6/site-packages/django/core/handlers/base.py", line 126, in _get_response
    response = wrapped_callback(request, *callback_args, **callback_kwargs)
  File "/home/miroslav/PycharmProjects/Project_nova_poshta-simulator/venv/lib/python3.6/site-packages/django/views/generic/base.py", line 69, in view
    return self.dispatch(request, *args, **kwargs)
  File "/home/miroslav/PycharmProjects/Project_nova_poshta-simulator/venv/lib/python3.6/site-packages/django/views/generic/base.py", line 89, in dispatch
    return handler(request, *args, **kwargs)
  File "/home/miroslav/PycharmProjects/Project_nova_poshta-simulator/venv/lib/python3.6/site-packages/django/views/generic/edit.py", line 142, in post
    return self.form_valid(form)
  File "/home/miroslav/PycharmProjects/Project_nova_poshta-simulator/nova_poshta/main/views.py", line 66, in form_valid
    message_creating.delay(self.request.user)
  File "/home/miroslav/PycharmProjects/Project_nova_poshta-simulator/venv/lib/python3.6/site-packages/celery/app/task.py", line 408, in delay
    return self.apply_async(args, kwargs)
  File "/home/miroslav/PycharmProjects/Project_nova_poshta-simulator/venv/lib/python3.6/site-packages/celery/app/task.py", line 535, in apply_async
    **options
  File "/home/miroslav/PycharmProjects/Project_nova_poshta-simulator/venv/lib/python3.6/site-packages/celery/app/base.py", line 745, in send_task
    amqp.send_task_message(P, name, message, **options)
  File "/home/miroslav/PycharmProjects/Project_nova_poshta-simulator/venv/lib/python3.6/site-packages/celery/app/amqp.py", line 552, in send_task_message
    **properties
  File "/home/miroslav/PycharmProjects/Project_nova_poshta-simulator/venv/lib/python3.6/site-packages/kombu/messaging.py", line 169, in publish
    compression, headers)
  File "/home/miroslav/PycharmProjects/Project_nova_poshta-simulator/venv/lib/python3.6/site-packages/kombu/messaging.py", line 252, in _prepare
    body) = dumps(body, serializer=serializer)
  File "/home/miroslav/PycharmProjects/Project_nova_poshta-simulator/venv/lib/python3.6/site-packages/kombu/serialization.py", line 221, in dumps
    payload = encoder(data)
  File "/usr/lib/python3.6/contextlib.py", line 99, in __exit__
    self.gen.throw(type, value, traceback)
  File "/home/miroslav/PycharmProjects/Project_nova_poshta-simulator/venv/lib/python3.6/site-packages/kombu/serialization.py", line 54, in _reraise_errors
    reraise(wrapper, wrapper(exc), sys.exc_info()[2])
  File "/home/miroslav/PycharmProjects/Project_nova_poshta-simulator/venv/lib/python3.6/site-packages/vine/five.py", line 178, in reraise
    raise value.with_traceback(tb)
  File "/home/miroslav/PycharmProjects/Project_nova_poshta-simulator/venv/lib/python3.6/site-packages/kombu/serialization.py", line 50, in _reraise_errors
    yield
  File "/home/miroslav/PycharmProjects/Project_nova_poshta-simulator/venv/lib/python3.6/site-packages/kombu/serialization.py", line 221, in dumps
    payload = encoder(data)
  File "/home/miroslav/PycharmProjects/Project_nova_poshta-simulator/venv/lib/python3.6/site-packages/kombu/utils/json.py", line 69, in dumps
    **dict(default_kwargs, **kwargs))
  File "/usr/lib/python3.6/json/__init__.py", line 238, in dumps
    **kw).encode(obj)
  File "/usr/lib/python3.6/json/encoder.py", line 199, in encode
    chunks = self.iterencode(o, _one_shot=True)
  File "/usr/lib/python3.6/json/encoder.py", line 257, in iterencode
    return _iterencode(o, 0)
  File "/home/miroslav/PycharmProjects/Project_nova_poshta-simulator/venv/lib/python3.6/site-packages/kombu/utils/json.py", line 59, in default
    return super(JSONEncoder, self).default(o)
  File "/usr/lib/python3.6/json/encoder.py", line 180, in default
    o.__class__.__name__)
kombu.exceptions.EncodeError: Object of type 'User' is not JSON serializable
Internal Server Error: /np/add_order
Traceback (most recent call last):
  File "/home/miroslav/PycharmProjects/Project_nova_poshta-simulator/venv/lib/python3.6/site-packages/kombu/serialization.py", line 50, in _reraise_errors
    yield
  File "/home/miroslav/PycharmProjects/Project_nova_poshta-simulator/venv/lib/python3.6/site-packages/kombu/serialization.py", line 221, in dumps
    payload = encoder(data)
  File "/home/miroslav/PycharmProjects/Project_nova_poshta-simulator/venv/lib/python3.6/site-packages/kombu/utils/json.py", line 69, in dumps
    **dict(default_kwargs, **kwargs))
  File "/usr/lib/python3.6/json/__init__.py", line 238, in dumps
    **kw).encode(obj)
  File "/usr/lib/python3.6/json/encoder.py", line 199, in encode
    chunks = self.iterencode(o, _one_shot=True)
  File "/usr/lib/python3.6/json/encoder.py", line 257, in iterencode
    return _iterencode(o, 0)
  File "/home/miroslav/PycharmProjects/Project_nova_poshta-simulator/venv/lib/python3.6/site-packages/kombu/utils/json.py", line 59, in default
    return super(JSONEncoder, self).default(o)
  File "/usr/lib/python3.6/json/encoder.py", line 180, in default
    o.__class__.__name__)
TypeError: Object of type 'WSGIRequest' is not JSON serializable

During handling of the above exception, another exception occurred:

Traceback (most recent call last):
  File "/home/miroslav/PycharmProjects/Project_nova_poshta-simulator/venv/lib/python3.6/site-packages/django/core/handlers/exception.py", line 35, in inner
    response = get_response(request)
  File "/home/miroslav/PycharmProjects/Project_nova_poshta-simulator/venv/lib/python3.6/site-packages/django/core/handlers/base.py", line 128, in _get_response
    response = self.process_exception_by_middleware(e, request)
  File "/home/miroslav/PycharmProjects/Project_nova_poshta-simulator/venv/lib/python3.6/site-packages/django/core/handlers/base.py", line 126, in _get_response
    response = wrapped_callback(request, *callback_args, **callback_kwargs)
  File "/home/miroslav/PycharmProjects/Project_nova_poshta-simulator/venv/lib/python3.6/site-packages/django/views/generic/base.py", line 69, in view
    return self.dispatch(request, *args, **kwargs)
  File "/home/miroslav/PycharmProjects/Project_nova_poshta-simulator/venv/lib/python3.6/site-packages/django/views/generic/base.py", line 89, in dispatch
    return handler(request, *args, **kwargs)
  File "/home/miroslav/PycharmProjects/Project_nova_poshta-simulator/venv/lib/python3.6/site-packages/django/views/generic/edit.py", line 142, in post
    return self.form_valid(form)
  File "/home/miroslav/PycharmProjects/Project_nova_poshta-simulator/nova_poshta/main/views.py", line 66, in form_valid
    message_creating.delay(self.request)
  File "/home/miroslav/PycharmProjects/Project_nova_poshta-simulator/venv/lib/python3.6/site-packages/celery/app/task.py", line 408, in delay
    return self.apply_async(args, kwargs)
  File "/home/miroslav/PycharmProjects/Project_nova_poshta-simulator/venv/lib/python3.6/site-packages/celery/app/task.py", line 535, in apply_async
    **options
  File "/home/miroslav/PycharmProjects/Project_nova_poshta-simulator/venv/lib/python3.6/site-packages/celery/app/base.py", line 745, in send_task
    amqp.send_task_message(P, name, message, **options)
  File "/home/miroslav/PycharmProjects/Project_nova_poshta-simulator/venv/lib/python3.6/site-packages/celery/app/amqp.py", line 552, in send_task_message
    **properties
  File "/home/miroslav/PycharmProjects/Project_nova_poshta-simulator/venv/lib/python3.6/site-packages/kombu/messaging.py", line 169, in publish
    compression, headers)
  File "/home/miroslav/PycharmProjects/Project_nova_poshta-simulator/venv/lib/python3.6/site-packages/kombu/messaging.py", line 252, in _prepare
    body) = dumps(body, serializer=serializer)
  File "/home/miroslav/PycharmProjects/Project_nova_poshta-simulator/venv/lib/python3.6/site-packages/kombu/serialization.py", line 221, in dumps
    payload = encoder(data)
  File "/usr/lib/python3.6/contextlib.py", line 99, in __exit__
    self.gen.throw(type, value, traceback)
  File "/home/miroslav/PycharmProjects/Project_nova_poshta-simulator/venv/lib/python3.6/site-packages/kombu/serialization.py", line 54, in _reraise_errors
    reraise(wrapper, wrapper(exc), sys.exc_info()[2])
  File "/home/miroslav/PycharmProjects/Project_nova_poshta-simulator/venv/lib/python3.6/site-packages/vine/five.py", line 178, in reraise
    raise value.with_traceback(tb)
  File "/home/miroslav/PycharmProjects/Project_nova_poshta-simulator/venv/lib/python3.6/site-packages/kombu/serialization.py", line 50, in _reraise_errors
    yield
  File "/home/miroslav/PycharmProjects/Project_nova_poshta-simulator/venv/lib/python3.6/site-packages/kombu/serialization.py", line 221, in dumps
    payload = encoder(data)
  File "/home/miroslav/PycharmProjects/Project_nova_poshta-simulator/venv/lib/python3.6/site-packages/kombu/utils/json.py", line 69, in dumps
    **dict(default_kwargs, **kwargs))
  File "/usr/lib/python3.6/json/__init__.py", line 238, in dumps
    **kw).encode(obj)
  File "/usr/lib/python3.6/json/encoder.py", line 199, in encode
    chunks = self.iterencode(o, _one_shot=True)
  File "/usr/lib/python3.6/json/encoder.py", line 257, in iterencode
    return _iterencode(o, 0)
  File "/home/miroslav/PycharmProjects/Project_nova_poshta-simulator/venv/lib/python3.6/site-packages/kombu/utils/json.py", line 59, in default
    return super(JSONEncoder, self).default(o)
  File "/usr/lib/python3.6/json/encoder.py", line 180, in default
    o.__class__.__name__)
kombu.exceptions.EncodeError: Object of type 'WSGIRequest' is not JSON serializable
Internal Server Error: /np/add_order
Traceback (most recent call last):
  File "/home/miroslav/PycharmProjects/Project_nova_poshta-simulator/venv/lib/python3.6/site-packages/kombu/serialization.py", line 50, in _reraise_errors
    yield
  File "/home/miroslav/PycharmProjects/Project_nova_poshta-simulator/venv/lib/python3.6/site-packages/kombu/serialization.py", line 221, in dumps
    payload = encoder(data)
  File "/home/miroslav/PycharmProjects/Project_nova_poshta-simulator/venv/lib/python3.6/site-packages/kombu/utils/json.py", line 69, in dumps
    **dict(default_kwargs, **kwargs))
  File "/usr/lib/python3.6/json/__init__.py", line 238, in dumps
    **kw).encode(obj)
  File "/usr/lib/python3.6/json/encoder.py", line 199, in encode
    chunks = self.iterencode(o, _one_shot=True)
  File "/usr/lib/python3.6/json/encoder.py", line 257, in iterencode
    return _iterencode(o, 0)
  File "/home/miroslav/PycharmProjects/Project_nova_poshta-simulator/venv/lib/python3.6/site-packages/kombu/utils/json.py", line 59, in default
    return super(JSONEncoder, self).default(o)
  File "/usr/lib/python3.6/json/encoder.py", line 180, in default
    o.__class__.__name__)
TypeError: Object of type 'User' is not JSON serializable

During handling of the above exception, another exception occurred:

Traceback (most recent call last):
  File "/home/miroslav/PycharmProjects/Project_nova_poshta-simulator/venv/lib/python3.6/site-packages/django/core/handlers/exception.py", line 35, in inner
    response = get_response(request)
  File "/home/miroslav/PycharmProjects/Project_nova_poshta-simulator/venv/lib/python3.6/site-packages/django/core/handlers/base.py", line 128, in _get_response
    response = self.process_exception_by_middleware(e, request)
  File "/home/miroslav/PycharmProjects/Project_nova_poshta-simulator/venv/lib/python3.6/site-packages/django/core/handlers/base.py", line 126, in _get_response
    response = wrapped_callback(request, *callback_args, **callback_kwargs)
  File "/home/miroslav/PycharmProjects/Project_nova_poshta-simulator/venv/lib/python3.6/site-packages/django/views/generic/base.py", line 69, in view
    return self.dispatch(request, *args, **kwargs)
  File "/home/miroslav/PycharmProjects/Project_nova_poshta-simulator/venv/lib/python3.6/site-packages/django/views/generic/base.py", line 89, in dispatch
    return handler(request, *args, **kwargs)
  File "/home/miroslav/PycharmProjects/Project_nova_poshta-simulator/venv/lib/python3.6/site-packages/django/views/generic/edit.py", line 142, in post
    return self.form_valid(form)
  File "/home/miroslav/PycharmProjects/Project_nova_poshta-simulator/nova_poshta/main/views.py", line 66, in form_valid
    message_creating.delay(self.request.user)
  File "/home/miroslav/PycharmProjects/Project_nova_poshta-simulator/venv/lib/python3.6/site-packages/celery/app/task.py", line 408, in delay
    return self.apply_async(args, kwargs)
  File "/home/miroslav/PycharmProjects/Project_nova_poshta-simulator/venv/lib/python3.6/site-packages/celery/app/task.py", line 535, in apply_async
    **options
  File "/home/miroslav/PycharmProjects/Project_nova_poshta-simulator/venv/lib/python3.6/site-packages/celery/app/base.py", line 745, in send_task
    amqp.send_task_message(P, name, message, **options)
  File "/home/miroslav/PycharmProjects/Project_nova_poshta-simulator/venv/lib/python3.6/site-packages/celery/app/amqp.py", line 552, in send_task_message
    **properties
  File "/home/miroslav/PycharmProjects/Project_nova_poshta-simulator/venv/lib/python3.6/site-packages/kombu/messaging.py", line 169, in publish
    compression, headers)
  File "/home/miroslav/PycharmProjects/Project_nova_poshta-simulator/venv/lib/python3.6/site-packages/kombu/messaging.py", line 252, in _prepare
    body) = dumps(body, serializer=serializer)
  File "/home/miroslav/PycharmProjects/Project_nova_poshta-simulator/venv/lib/python3.6/site-packages/kombu/serialization.py", line 221, in dumps
    payload = encoder(data)
  File "/usr/lib/python3.6/contextlib.py", line 99, in __exit__
    self.gen.throw(type, value, traceback)
  File "/home/miroslav/PycharmProjects/Project_nova_poshta-simulator/venv/lib/python3.6/site-packages/kombu/serialization.py", line 54, in _reraise_errors
    reraise(wrapper, wrapper(exc), sys.exc_info()[2])
  File "/home/miroslav/PycharmProjects/Project_nova_poshta-simulator/venv/lib/python3.6/site-packages/vine/five.py", line 178, in reraise
    raise value.with_traceback(tb)
  File "/home/miroslav/PycharmProjects/Project_nova_poshta-simulator/venv/lib/python3.6/site-packages/kombu/serialization.py", line 50, in _reraise_errors
    yield
  File "/home/miroslav/PycharmProjects/Project_nova_poshta-simulator/venv/lib/python3.6/site-packages/kombu/serialization.py", line 221, in dumps
    payload = encoder(data)
  File "/home/miroslav/PycharmProjects/Project_nova_poshta-simulator/venv/lib/python3.6/site-packages/kombu/utils/json.py", line 69, in dumps
    **dict(default_kwargs, **kwargs))
  File "/usr/lib/python3.6/json/__init__.py", line 238, in dumps
    **kw).encode(obj)
  File "/usr/lib/python3.6/json/encoder.py", line 199, in encode
    chunks = self.iterencode(o, _one_shot=True)
  File "/usr/lib/python3.6/json/encoder.py", line 257, in iterencode
    return _iterencode(o, 0)
  File "/home/miroslav/PycharmProjects/Project_nova_poshta-simulator/venv/lib/python3.6/site-packages/kombu/utils/json.py", line 59, in default
    return super(JSONEncoder, self).default(o)
  File "/usr/lib/python3.6/json/encoder.py", line 180, in default
    o.__class__.__name__)
kombu.exceptions.EncodeError: Object of type 'User' is not JSON serializable
Internal Server Error: /np/add_order
Traceback (most recent call last):
  File "/home/miroslav/PycharmProjects/Project_nova_poshta-simulator/venv/lib/python3.6/site-packages/kombu/serialization.py", line 50, in _reraise_errors
    yield
  File "/home/miroslav/PycharmProjects/Project_nova_poshta-simulator/venv/lib/python3.6/site-packages/kombu/serialization.py", line 221, in dumps
    payload = encoder(data)
  File "/home/miroslav/PycharmProjects/Project_nova_poshta-simulator/venv/lib/python3.6/site-packages/kombu/utils/json.py", line 69, in dumps
    **dict(default_kwargs, **kwargs))
  File "/usr/lib/python3.6/json/__init__.py", line 238, in dumps
    **kw).encode(obj)
  File "/usr/lib/python3.6/json/encoder.py", line 199, in encode
    chunks = self.iterencode(o, _one_shot=True)
  File "/usr/lib/python3.6/json/encoder.py", line 257, in iterencode
    return _iterencode(o, 0)
  File "/home/miroslav/PycharmProjects/Project_nova_poshta-simulator/venv/lib/python3.6/site-packages/kombu/utils/json.py", line 59, in default
    return super(JSONEncoder, self).default(o)
  File "/usr/lib/python3.6/json/encoder.py", line 180, in default
    o.__class__.__name__)
TypeError: Object of type 'User' is not JSON serializable

During handling of the above exception, another exception occurred:

Traceback (most recent call last):
  File "/home/miroslav/PycharmProjects/Project_nova_poshta-simulator/venv/lib/python3.6/site-packages/django/core/handlers/exception.py", line 35, in inner
    response = get_response(request)
  File "/home/miroslav/PycharmProjects/Project_nova_poshta-simulator/venv/lib/python3.6/site-packages/django/core/handlers/base.py", line 128, in _get_response
    response = self.process_exception_by_middleware(e, request)
  File "/home/miroslav/PycharmProjects/Project_nova_poshta-simulator/venv/lib/python3.6/site-packages/django/core/handlers/base.py", line 126, in _get_response
    response = wrapped_callback(request, *callback_args, **callback_kwargs)
  File "/home/miroslav/PycharmProjects/Project_nova_poshta-simulator/venv/lib/python3.6/site-packages/django/views/generic/base.py", line 69, in view
    return self.dispatch(request, *args, **kwargs)
  File "/home/miroslav/PycharmProjects/Project_nova_poshta-simulator/venv/lib/python3.6/site-packages/django/views/generic/base.py", line 89, in dispatch
    return handler(request, *args, **kwargs)
  File "/home/miroslav/PycharmProjects/Project_nova_poshta-simulator/venv/lib/python3.6/site-packages/django/views/generic/edit.py", line 142, in post
    return self.form_valid(form)
  File "/home/miroslav/PycharmProjects/Project_nova_poshta-simulator/nova_poshta/main/views.py", line 66, in form_valid
    message_creating.delay(self.request.user)
  File "/home/miroslav/PycharmProjects/Project_nova_poshta-simulator/venv/lib/python3.6/site-packages/celery/app/task.py", line 408, in delay
    return self.apply_async(args, kwargs)
  File "/home/miroslav/PycharmProjects/Project_nova_poshta-simulator/venv/lib/python3.6/site-packages/celery/app/task.py", line 535, in apply_async
    **options
  File "/home/miroslav/PycharmProjects/Project_nova_poshta-simulator/venv/lib/python3.6/site-packages/celery/app/base.py", line 745, in send_task
    amqp.send_task_message(P, name, message, **options)
  File "/home/miroslav/PycharmProjects/Project_nova_poshta-simulator/venv/lib/python3.6/site-packages/celery/app/amqp.py", line 552, in send_task_message
    **properties
  File "/home/miroslav/PycharmProjects/Project_nova_poshta-simulator/venv/lib/python3.6/site-packages/kombu/messaging.py", line 169, in publish
    compression, headers)
  File "/home/miroslav/PycharmProjects/Project_nova_poshta-simulator/venv/lib/python3.6/site-packages/kombu/messaging.py", line 252, in _prepare
    body) = dumps(body, serializer=serializer)
  File "/home/miroslav/PycharmProjects/Project_nova_poshta-simulator/venv/lib/python3.6/site-packages/kombu/serialization.py", line 221, in dumps
    payload = encoder(data)
  File "/usr/lib/python3.6/contextlib.py", line 99, in __exit__
    self.gen.throw(type, value, traceback)
  File "/home/miroslav/PycharmProjects/Project_nova_poshta-simulator/venv/lib/python3.6/site-packages/kombu/serialization.py", line 54, in _reraise_errors
    reraise(wrapper, wrapper(exc), sys.exc_info()[2])
  File "/home/miroslav/PycharmProjects/Project_nova_poshta-simulator/venv/lib/python3.6/site-packages/vine/five.py", line 178, in reraise
    raise value.with_traceback(tb)
  File "/home/miroslav/PycharmProjects/Project_nova_poshta-simulator/venv/lib/python3.6/site-packages/kombu/serialization.py", line 50, in _reraise_errors
    yield
  File "/home/miroslav/PycharmProjects/Project_nova_poshta-simulator/venv/lib/python3.6/site-packages/kombu/serialization.py", line 221, in dumps
    payload = encoder(data)
  File "/home/miroslav/PycharmProjects/Project_nova_poshta-simulator/venv/lib/python3.6/site-packages/kombu/utils/json.py", line 69, in dumps
    **dict(default_kwargs, **kwargs))
  File "/usr/lib/python3.6/json/__init__.py", line 238, in dumps
    **kw).encode(obj)
  File "/usr/lib/python3.6/json/encoder.py", line 199, in encode
    chunks = self.iterencode(o, _one_shot=True)
  File "/usr/lib/python3.6/json/encoder.py", line 257, in iterencode
    return _iterencode(o, 0)
  File "/home/miroslav/PycharmProjects/Project_nova_poshta-simulator/venv/lib/python3.6/site-packages/kombu/utils/json.py", line 59, in default
    return super(JSONEncoder, self).default(o)
  File "/usr/lib/python3.6/json/encoder.py", line 180, in default
    o.__class__.__name__)
kombu.exceptions.EncodeError: Object of type 'User' is not JSON serializable
Internal Server Error: /np/add_order
Traceback (most recent call last):
  File "/home/miroslav/PycharmProjects/Project_nova_poshta-simulator/venv/lib/python3.6/site-packages/kombu/serialization.py", line 50, in _reraise_errors
    yield
  File "/home/miroslav/PycharmProjects/Project_nova_poshta-simulator/venv/lib/python3.6/site-packages/kombu/serialization.py", line 221, in dumps
    payload = encoder(data)
  File "/home/miroslav/PycharmProjects/Project_nova_poshta-simulator/venv/lib/python3.6/site-packages/kombu/utils/json.py", line 69, in dumps
    **dict(default_kwargs, **kwargs))
  File "/usr/lib/python3.6/json/__init__.py", line 238, in dumps
    **kw).encode(obj)
  File "/usr/lib/python3.6/json/encoder.py", line 199, in encode
    chunks = self.iterencode(o, _one_shot=True)
  File "/usr/lib/python3.6/json/encoder.py", line 257, in iterencode
    return _iterencode(o, 0)
  File "/home/miroslav/PycharmProjects/Project_nova_poshta-simulator/venv/lib/python3.6/site-packages/kombu/utils/json.py", line 59, in default
    return super(JSONEncoder, self).default(o)
  File "/usr/lib/python3.6/json/encoder.py", line 180, in default
    o.__class__.__name__)
TypeError: Object of type 'User' is not JSON serializable

During handling of the above exception, another exception occurred:

Traceback (most recent call last):
  File "/home/miroslav/PycharmProjects/Project_nova_poshta-simulator/venv/lib/python3.6/site-packages/django/core/handlers/exception.py", line 35, in inner
    response = get_response(request)
  File "/home/miroslav/PycharmProjects/Project_nova_poshta-simulator/venv/lib/python3.6/site-packages/django/core/handlers/base.py", line 128, in _get_response
    response = self.process_exception_by_middleware(e, request)
  File "/home/miroslav/PycharmProjects/Project_nova_poshta-simulator/venv/lib/python3.6/site-packages/django/core/handlers/base.py", line 126, in _get_response
    response = wrapped_callback(request, *callback_args, **callback_kwargs)
  File "/home/miroslav/PycharmProjects/Project_nova_poshta-simulator/venv/lib/python3.6/site-packages/django/views/generic/base.py", line 69, in view
    return self.dispatch(request, *args, **kwargs)
  File "/home/miroslav/PycharmProjects/Project_nova_poshta-simulator/venv/lib/python3.6/site-packages/django/views/generic/base.py", line 89, in dispatch
    return handler(request, *args, **kwargs)
  File "/home/miroslav/PycharmProjects/Project_nova_poshta-simulator/venv/lib/python3.6/site-packages/django/views/generic/edit.py", line 142, in post
    return self.form_valid(form)
  File "/home/miroslav/PycharmProjects/Project_nova_poshta-simulator/nova_poshta/main/views.py", line 66, in form_valid
    message_creating.delay(self.request.user)
  File "/home/miroslav/PycharmProjects/Project_nova_poshta-simulator/venv/lib/python3.6/site-packages/celery/app/task.py", line 408, in delay
    return self.apply_async(args, kwargs)
  File "/home/miroslav/PycharmProjects/Project_nova_poshta-simulator/venv/lib/python3.6/site-packages/celery/app/task.py", line 535, in apply_async
    **options
  File "/home/miroslav/PycharmProjects/Project_nova_poshta-simulator/venv/lib/python3.6/site-packages/celery/app/base.py", line 745, in send_task
    amqp.send_task_message(P, name, message, **options)
  File "/home/miroslav/PycharmProjects/Project_nova_poshta-simulator/venv/lib/python3.6/site-packages/celery/app/amqp.py", line 552, in send_task_message
    **properties
  File "/home/miroslav/PycharmProjects/Project_nova_poshta-simulator/venv/lib/python3.6/site-packages/kombu/messaging.py", line 169, in publish
    compression, headers)
  File "/home/miroslav/PycharmProjects/Project_nova_poshta-simulator/venv/lib/python3.6/site-packages/kombu/messaging.py", line 252, in _prepare
    body) = dumps(body, serializer=serializer)
  File "/home/miroslav/PycharmProjects/Project_nova_poshta-simulator/venv/lib/python3.6/site-packages/kombu/serialization.py", line 221, in dumps
    payload = encoder(data)
  File "/usr/lib/python3.6/contextlib.py", line 99, in __exit__
    self.gen.throw(type, value, traceback)
  File "/home/miroslav/PycharmProjects/Project_nova_poshta-simulator/venv/lib/python3.6/site-packages/kombu/serialization.py", line 54, in _reraise_errors
    reraise(wrapper, wrapper(exc), sys.exc_info()[2])
  File "/home/miroslav/PycharmProjects/Project_nova_poshta-simulator/venv/lib/python3.6/site-packages/vine/five.py", line 178, in reraise
    raise value.with_traceback(tb)
  File "/home/miroslav/PycharmProjects/Project_nova_poshta-simulator/venv/lib/python3.6/site-packages/kombu/serialization.py", line 50, in _reraise_errors
    yield
  File "/home/miroslav/PycharmProjects/Project_nova_poshta-simulator/venv/lib/python3.6/site-packages/kombu/serialization.py", line 221, in dumps
    payload = encoder(data)
  File "/home/miroslav/PycharmProjects/Project_nova_poshta-simulator/venv/lib/python3.6/site-packages/kombu/utils/json.py", line 69, in dumps
    **dict(default_kwargs, **kwargs))
  File "/usr/lib/python3.6/json/__init__.py", line 238, in dumps
    **kw).encode(obj)
  File "/usr/lib/python3.6/json/encoder.py", line 199, in encode
    chunks = self.iterencode(o, _one_shot=True)
  File "/usr/lib/python3.6/json/encoder.py", line 257, in iterencode
    return _iterencode(o, 0)
  File "/home/miroslav/PycharmProjects/Project_nova_poshta-simulator/venv/lib/python3.6/site-packages/kombu/utils/json.py", line 59, in default
    return super(JSONEncoder, self).default(o)
  File "/usr/lib/python3.6/json/encoder.py", line 180, in default
    o.__class__.__name__)
kombu.exceptions.EncodeError: Object of type 'User' is not JSON serializable
Internal Server Error: /np/add_order
Traceback (most recent call last):
  File "/home/miroslav/PycharmProjects/Project_nova_poshta-simulator/venv/lib/python3.6/site-packages/kombu/serialization.py", line 50, in _reraise_errors
    yield
  File "/home/miroslav/PycharmProjects/Project_nova_poshta-simulator/venv/lib/python3.6/site-packages/kombu/serialization.py", line 221, in dumps
    payload = encoder(data)
  File "/home/miroslav/PycharmProjects/Project_nova_poshta-simulator/venv/lib/python3.6/site-packages/kombu/utils/json.py", line 69, in dumps
    **dict(default_kwargs, **kwargs))
  File "/usr/lib/python3.6/json/__init__.py", line 238, in dumps
    **kw).encode(obj)
  File "/usr/lib/python3.6/json/encoder.py", line 199, in encode
    chunks = self.iterencode(o, _one_shot=True)
  File "/usr/lib/python3.6/json/encoder.py", line 257, in iterencode
    return _iterencode(o, 0)
  File "/home/miroslav/PycharmProjects/Project_nova_poshta-simulator/venv/lib/python3.6/site-packages/kombu/utils/json.py", line 59, in default
    return super(JSONEncoder, self).default(o)
  File "/usr/lib/python3.6/json/encoder.py", line 180, in default
    o.__class__.__name__)
TypeError: Object of type 'User' is not JSON serializable

During handling of the above exception, another exception occurred:

Traceback (most recent call last):
  File "/home/miroslav/PycharmProjects/Project_nova_poshta-simulator/venv/lib/python3.6/site-packages/django/core/handlers/exception.py", line 35, in inner
    response = get_response(request)
  File "/home/miroslav/PycharmProjects/Project_nova_poshta-simulator/venv/lib/python3.6/site-packages/django/core/handlers/base.py", line 128, in _get_response
    response = self.process_exception_by_middleware(e, request)
  File "/home/miroslav/PycharmProjects/Project_nova_poshta-simulator/venv/lib/python3.6/site-packages/django/core/handlers/base.py", line 126, in _get_response
    response = wrapped_callback(request, *callback_args, **callback_kwargs)
  File "/home/miroslav/PycharmProjects/Project_nova_poshta-simulator/venv/lib/python3.6/site-packages/django/views/generic/base.py", line 69, in view
    return self.dispatch(request, *args, **kwargs)
  File "/home/miroslav/PycharmProjects/Project_nova_poshta-simulator/venv/lib/python3.6/site-packages/django/views/generic/base.py", line 89, in dispatch
    return handler(request, *args, **kwargs)
  File "/home/miroslav/PycharmProjects/Project_nova_poshta-simulator/venv/lib/python3.6/site-packages/django/views/generic/edit.py", line 142, in post
    return self.form_valid(form)
  File "/home/miroslav/PycharmProjects/Project_nova_poshta-simulator/nova_poshta/main/views.py", line 66, in form_valid
    message_creating.delay(self.request.user)
  File "/home/miroslav/PycharmProjects/Project_nova_poshta-simulator/venv/lib/python3.6/site-packages/celery/app/task.py", line 408, in delay
    return self.apply_async(args, kwargs)
  File "/home/miroslav/PycharmProjects/Project_nova_poshta-simulator/venv/lib/python3.6/site-packages/celery/app/task.py", line 535, in apply_async
    **options
  File "/home/miroslav/PycharmProjects/Project_nova_poshta-simulator/venv/lib/python3.6/site-packages/celery/app/base.py", line 745, in send_task
    amqp.send_task_message(P, name, message, **options)
  File "/home/miroslav/PycharmProjects/Project_nova_poshta-simulator/venv/lib/python3.6/site-packages/celery/app/amqp.py", line 552, in send_task_message
    **properties
  File "/home/miroslav/PycharmProjects/Project_nova_poshta-simulator/venv/lib/python3.6/site-packages/kombu/messaging.py", line 169, in publish
    compression, headers)
  File "/home/miroslav/PycharmProjects/Project_nova_poshta-simulator/venv/lib/python3.6/site-packages/kombu/messaging.py", line 252, in _prepare
    body) = dumps(body, serializer=serializer)
  File "/home/miroslav/PycharmProjects/Project_nova_poshta-simulator/venv/lib/python3.6/site-packages/kombu/serialization.py", line 221, in dumps
    payload = encoder(data)
  File "/usr/lib/python3.6/contextlib.py", line 99, in __exit__
    self.gen.throw(type, value, traceback)
  File "/home/miroslav/PycharmProjects/Project_nova_poshta-simulator/venv/lib/python3.6/site-packages/kombu/serialization.py", line 54, in _reraise_errors
    reraise(wrapper, wrapper(exc), sys.exc_info()[2])
  File "/home/miroslav/PycharmProjects/Project_nova_poshta-simulator/venv/lib/python3.6/site-packages/vine/five.py", line 178, in reraise
    raise value.with_traceback(tb)
  File "/home/miroslav/PycharmProjects/Project_nova_poshta-simulator/venv/lib/python3.6/site-packages/kombu/serialization.py", line 50, in _reraise_errors
    yield
  File "/home/miroslav/PycharmProjects/Project_nova_poshta-simulator/venv/lib/python3.6/site-packages/kombu/serialization.py", line 221, in dumps
    payload = encoder(data)
  File "/home/miroslav/PycharmProjects/Project_nova_poshta-simulator/venv/lib/python3.6/site-packages/kombu/utils/json.py", line 69, in dumps
    **dict(default_kwargs, **kwargs))
  File "/usr/lib/python3.6/json/__init__.py", line 238, in dumps
    **kw).encode(obj)
  File "/usr/lib/python3.6/json/encoder.py", line 199, in encode
    chunks = self.iterencode(o, _one_shot=True)
  File "/usr/lib/python3.6/json/encoder.py", line 257, in iterencode
    return _iterencode(o, 0)
  File "/home/miroslav/PycharmProjects/Project_nova_poshta-simulator/venv/lib/python3.6/site-packages/kombu/utils/json.py", line 59, in default
    return super(JSONEncoder, self).default(o)
  File "/usr/lib/python3.6/json/encoder.py", line 180, in default
    o.__class__.__name__)
kombu.exceptions.EncodeError: Object of type 'User' is not JSON serializable
Internal Server Error: /np/add_order
Traceback (most recent call last):
  File "/home/miroslav/PycharmProjects/Project_nova_poshta-simulator/venv/lib/python3.6/site-packages/kombu/serialization.py", line 50, in _reraise_errors
    yield
  File "/home/miroslav/PycharmProjects/Project_nova_poshta-simulator/venv/lib/python3.6/site-packages/kombu/serialization.py", line 221, in dumps
    payload = encoder(data)
  File "/home/miroslav/PycharmProjects/Project_nova_poshta-simulator/venv/lib/python3.6/site-packages/kombu/utils/json.py", line 69, in dumps
    **dict(default_kwargs, **kwargs))
  File "/usr/lib/python3.6/json/__init__.py", line 238, in dumps
    **kw).encode(obj)
  File "/usr/lib/python3.6/json/encoder.py", line 199, in encode
    chunks = self.iterencode(o, _one_shot=True)
  File "/usr/lib/python3.6/json/encoder.py", line 257, in iterencode
    return _iterencode(o, 0)
  File "/home/miroslav/PycharmProjects/Project_nova_poshta-simulator/venv/lib/python3.6/site-packages/kombu/utils/json.py", line 59, in default
    return super(JSONEncoder, self).default(o)
  File "/usr/lib/python3.6/json/encoder.py", line 180, in default
    o.__class__.__name__)
TypeError: Object of type 'User' is not JSON serializable

During handling of the above exception, another exception occurred:

Traceback (most recent call last):
  File "/home/miroslav/PycharmProjects/Project_nova_poshta-simulator/venv/lib/python3.6/site-packages/django/core/handlers/exception.py", line 35, in inner
    response = get_response(request)
  File "/home/miroslav/PycharmProjects/Project_nova_poshta-simulator/venv/lib/python3.6/site-packages/django/core/handlers/base.py", line 128, in _get_response
    response = self.process_exception_by_middleware(e, request)
  File "/home/miroslav/PycharmProjects/Project_nova_poshta-simulator/venv/lib/python3.6/site-packages/django/core/handlers/base.py", line 126, in _get_response
    response = wrapped_callback(request, *callback_args, **callback_kwargs)
  File "/home/miroslav/PycharmProjects/Project_nova_poshta-simulator/venv/lib/python3.6/site-packages/django/views/generic/base.py", line 69, in view
    return self.dispatch(request, *args, **kwargs)
  File "/home/miroslav/PycharmProjects/Project_nova_poshta-simulator/venv/lib/python3.6/site-packages/django/views/generic/base.py", line 89, in dispatch
    return handler(request, *args, **kwargs)
  File "/home/miroslav/PycharmProjects/Project_nova_poshta-simulator/venv/lib/python3.6/site-packages/django/views/generic/edit.py", line 142, in post
    return self.form_valid(form)
  File "/home/miroslav/PycharmProjects/Project_nova_poshta-simulator/nova_poshta/main/views.py", line 66, in form_valid
    message_creating.delay(self.request.user)
  File "/home/miroslav/PycharmProjects/Project_nova_poshta-simulator/venv/lib/python3.6/site-packages/celery/app/task.py", line 408, in delay
    return self.apply_async(args, kwargs)
  File "/home/miroslav/PycharmProjects/Project_nova_poshta-simulator/venv/lib/python3.6/site-packages/celery/app/task.py", line 535, in apply_async
    **options
  File "/home/miroslav/PycharmProjects/Project_nova_poshta-simulator/venv/lib/python3.6/site-packages/celery/app/base.py", line 745, in send_task
    amqp.send_task_message(P, name, message, **options)
  File "/home/miroslav/PycharmProjects/Project_nova_poshta-simulator/venv/lib/python3.6/site-packages/celery/app/amqp.py", line 552, in send_task_message
    **properties
  File "/home/miroslav/PycharmProjects/Project_nova_poshta-simulator/venv/lib/python3.6/site-packages/kombu/messaging.py", line 169, in publish
    compression, headers)
  File "/home/miroslav/PycharmProjects/Project_nova_poshta-simulator/venv/lib/python3.6/site-packages/kombu/messaging.py", line 252, in _prepare
    body) = dumps(body, serializer=serializer)
  File "/home/miroslav/PycharmProjects/Project_nova_poshta-simulator/venv/lib/python3.6/site-packages/kombu/serialization.py", line 221, in dumps
    payload = encoder(data)
  File "/usr/lib/python3.6/contextlib.py", line 99, in __exit__
    self.gen.throw(type, value, traceback)
  File "/home/miroslav/PycharmProjects/Project_nova_poshta-simulator/venv/lib/python3.6/site-packages/kombu/serialization.py", line 54, in _reraise_errors
    reraise(wrapper, wrapper(exc), sys.exc_info()[2])
  File "/home/miroslav/PycharmProjects/Project_nova_poshta-simulator/venv/lib/python3.6/site-packages/vine/five.py", line 178, in reraise
    raise value.with_traceback(tb)
  File "/home/miroslav/PycharmProjects/Project_nova_poshta-simulator/venv/lib/python3.6/site-packages/kombu/serialization.py", line 50, in _reraise_errors
    yield
  File "/home/miroslav/PycharmProjects/Project_nova_poshta-simulator/venv/lib/python3.6/site-packages/kombu/serialization.py", line 221, in dumps
    payload = encoder(data)
  File "/home/miroslav/PycharmProjects/Project_nova_poshta-simulator/venv/lib/python3.6/site-packages/kombu/utils/json.py", line 69, in dumps
    **dict(default_kwargs, **kwargs))
  File "/usr/lib/python3.6/json/__init__.py", line 238, in dumps
    **kw).encode(obj)
  File "/usr/lib/python3.6/json/encoder.py", line 199, in encode
    chunks = self.iterencode(o, _one_shot=True)
  File "/usr/lib/python3.6/json/encoder.py", line 257, in iterencode
    return _iterencode(o, 0)
  File "/home/miroslav/PycharmProjects/Project_nova_poshta-simulator/venv/lib/python3.6/site-packages/kombu/utils/json.py", line 59, in default
    return super(JSONEncoder, self).default(o)
  File "/usr/lib/python3.6/json/encoder.py", line 180, in default
    o.__class__.__name__)
kombu.exceptions.EncodeError: Object of type 'User' is not JSON serializable
Internal Server Error: /np/add_order
Traceback (most recent call last):
  File "/home/miroslav/PycharmProjects/Project_nova_poshta-simulator/venv/lib/python3.6/site-packages/kombu/serialization.py", line 50, in _reraise_errors
    yield
  File "/home/miroslav/PycharmProjects/Project_nova_poshta-simulator/venv/lib/python3.6/site-packages/kombu/serialization.py", line 221, in dumps
    payload = encoder(data)
  File "/home/miroslav/PycharmProjects/Project_nova_poshta-simulator/venv/lib/python3.6/site-packages/kombu/utils/json.py", line 69, in dumps
    **dict(default_kwargs, **kwargs))
  File "/usr/lib/python3.6/json/__init__.py", line 238, in dumps
    **kw).encode(obj)
  File "/usr/lib/python3.6/json/encoder.py", line 199, in encode
    chunks = self.iterencode(o, _one_shot=True)
  File "/usr/lib/python3.6/json/encoder.py", line 257, in iterencode
    return _iterencode(o, 0)
  File "/home/miroslav/PycharmProjects/Project_nova_poshta-simulator/venv/lib/python3.6/site-packages/kombu/utils/json.py", line 59, in default
    return super(JSONEncoder, self).default(o)
  File "/usr/lib/python3.6/json/encoder.py", line 180, in default
    o.__class__.__name__)
TypeError: Object of type 'User' is not JSON serializable

During handling of the above exception, another exception occurred:

Traceback (most recent call last):
  File "/home/miroslav/PycharmProjects/Project_nova_poshta-simulator/venv/lib/python3.6/site-packages/django/core/handlers/exception.py", line 35, in inner
    response = get_response(request)
  File "/home/miroslav/PycharmProjects/Project_nova_poshta-simulator/venv/lib/python3.6/site-packages/django/core/handlers/base.py", line 128, in _get_response
    response = self.process_exception_by_middleware(e, request)
  File "/home/miroslav/PycharmProjects/Project_nova_poshta-simulator/venv/lib/python3.6/site-packages/django/core/handlers/base.py", line 126, in _get_response
    response = wrapped_callback(request, *callback_args, **callback_kwargs)
  File "/home/miroslav/PycharmProjects/Project_nova_poshta-simulator/venv/lib/python3.6/site-packages/django/views/generic/base.py", line 69, in view
    return self.dispatch(request, *args, **kwargs)
  File "/home/miroslav/PycharmProjects/Project_nova_poshta-simulator/venv/lib/python3.6/site-packages/django/views/generic/base.py", line 89, in dispatch
    return handler(request, *args, **kwargs)
  File "/home/miroslav/PycharmProjects/Project_nova_poshta-simulator/venv/lib/python3.6/site-packages/django/views/generic/edit.py", line 142, in post
    return self.form_valid(form)
  File "/home/miroslav/PycharmProjects/Project_nova_poshta-simulator/nova_poshta/main/views.py", line 66, in form_valid
    message_creating.delay(self.request.user)
  File "/home/miroslav/PycharmProjects/Project_nova_poshta-simulator/venv/lib/python3.6/site-packages/celery/app/task.py", line 408, in delay
    return self.apply_async(args, kwargs)
  File "/home/miroslav/PycharmProjects/Project_nova_poshta-simulator/venv/lib/python3.6/site-packages/celery/app/task.py", line 535, in apply_async
    **options
  File "/home/miroslav/PycharmProjects/Project_nova_poshta-simulator/venv/lib/python3.6/site-packages/celery/app/base.py", line 745, in send_task
    amqp.send_task_message(P, name, message, **options)
  File "/home/miroslav/PycharmProjects/Project_nova_poshta-simulator/venv/lib/python3.6/site-packages/celery/app/amqp.py", line 552, in send_task_message
    **properties
  File "/home/miroslav/PycharmProjects/Project_nova_poshta-simulator/venv/lib/python3.6/site-packages/kombu/messaging.py", line 169, in publish
    compression, headers)
  File "/home/miroslav/PycharmProjects/Project_nova_poshta-simulator/venv/lib/python3.6/site-packages/kombu/messaging.py", line 252, in _prepare
    body) = dumps(body, serializer=serializer)
  File "/home/miroslav/PycharmProjects/Project_nova_poshta-simulator/venv/lib/python3.6/site-packages/kombu/serialization.py", line 221, in dumps
    payload = encoder(data)
  File "/usr/lib/python3.6/contextlib.py", line 99, in __exit__
    self.gen.throw(type, value, traceback)
  File "/home/miroslav/PycharmProjects/Project_nova_poshta-simulator/venv/lib/python3.6/site-packages/kombu/serialization.py", line 54, in _reraise_errors
    reraise(wrapper, wrapper(exc), sys.exc_info()[2])
  File "/home/miroslav/PycharmProjects/Project_nova_poshta-simulator/venv/lib/python3.6/site-packages/vine/five.py", line 178, in reraise
    raise value.with_traceback(tb)
  File "/home/miroslav/PycharmProjects/Project_nova_poshta-simulator/venv/lib/python3.6/site-packages/kombu/serialization.py", line 50, in _reraise_errors
    yield
  File "/home/miroslav/PycharmProjects/Project_nova_poshta-simulator/venv/lib/python3.6/site-packages/kombu/serialization.py", line 221, in dumps
    payload = encoder(data)
  File "/home/miroslav/PycharmProjects/Project_nova_poshta-simulator/venv/lib/python3.6/site-packages/kombu/utils/json.py", line 69, in dumps
    **dict(default_kwargs, **kwargs))
  File "/usr/lib/python3.6/json/__init__.py", line 238, in dumps
    **kw).encode(obj)
  File "/usr/lib/python3.6/json/encoder.py", line 199, in encode
    chunks = self.iterencode(o, _one_shot=True)
  File "/usr/lib/python3.6/json/encoder.py", line 257, in iterencode
    return _iterencode(o, 0)
  File "/home/miroslav/PycharmProjects/Project_nova_poshta-simulator/venv/lib/python3.6/site-packages/kombu/utils/json.py", line 59, in default
    return super(JSONEncoder, self).default(o)
  File "/usr/lib/python3.6/json/encoder.py", line 180, in default
    o.__class__.__name__)
kombu.exceptions.EncodeError: Object of type 'User' is not JSON serializable
Internal Server Error: /np/add_order
Traceback (most recent call last):
  File "/home/miroslav/PycharmProjects/Project_nova_poshta-simulator/venv/lib/python3.6/site-packages/kombu/serialization.py", line 50, in _reraise_errors
    yield
  File "/home/miroslav/PycharmProjects/Project_nova_poshta-simulator/venv/lib/python3.6/site-packages/kombu/serialization.py", line 221, in dumps
    payload = encoder(data)
  File "/home/miroslav/PycharmProjects/Project_nova_poshta-simulator/venv/lib/python3.6/site-packages/kombu/utils/json.py", line 69, in dumps
    **dict(default_kwargs, **kwargs))
  File "/usr/lib/python3.6/json/__init__.py", line 238, in dumps
    **kw).encode(obj)
  File "/usr/lib/python3.6/json/encoder.py", line 199, in encode
    chunks = self.iterencode(o, _one_shot=True)
  File "/usr/lib/python3.6/json/encoder.py", line 257, in iterencode
    return _iterencode(o, 0)
  File "/home/miroslav/PycharmProjects/Project_nova_poshta-simulator/venv/lib/python3.6/site-packages/kombu/utils/json.py", line 59, in default
    return super(JSONEncoder, self).default(o)
  File "/usr/lib/python3.6/json/encoder.py", line 180, in default
    o.__class__.__name__)
TypeError: Object of type 'User' is not JSON serializable

During handling of the above exception, another exception occurred:

Traceback (most recent call last):
  File "/home/miroslav/PycharmProjects/Project_nova_poshta-simulator/venv/lib/python3.6/site-packages/django/core/handlers/exception.py", line 35, in inner
    response = get_response(request)
  File "/home/miroslav/PycharmProjects/Project_nova_poshta-simulator/venv/lib/python3.6/site-packages/django/core/handlers/base.py", line 128, in _get_response
    response = self.process_exception_by_middleware(e, request)
  File "/home/miroslav/PycharmProjects/Project_nova_poshta-simulator/venv/lib/python3.6/site-packages/django/core/handlers/base.py", line 126, in _get_response
    response = wrapped_callback(request, *callback_args, **callback_kwargs)
  File "/home/miroslav/PycharmProjects/Project_nova_poshta-simulator/venv/lib/python3.6/site-packages/django/views/generic/base.py", line 69, in view
    return self.dispatch(request, *args, **kwargs)
  File "/home/miroslav/PycharmProjects/Project_nova_poshta-simulator/venv/lib/python3.6/site-packages/django/views/generic/base.py", line 89, in dispatch
    return handler(request, *args, **kwargs)
  File "/home/miroslav/PycharmProjects/Project_nova_poshta-simulator/venv/lib/python3.6/site-packages/django/views/generic/edit.py", line 142, in post
    return self.form_valid(form)
  File "/home/miroslav/PycharmProjects/Project_nova_poshta-simulator/nova_poshta/main/views.py", line 66, in form_valid
    message_creating.delay(self.request.user)
  File "/home/miroslav/PycharmProjects/Project_nova_poshta-simulator/venv/lib/python3.6/site-packages/celery/app/task.py", line 408, in delay
    return self.apply_async(args, kwargs)
  File "/home/miroslav/PycharmProjects/Project_nova_poshta-simulator/venv/lib/python3.6/site-packages/celery/app/task.py", line 535, in apply_async
    **options
  File "/home/miroslav/PycharmProjects/Project_nova_poshta-simulator/venv/lib/python3.6/site-packages/celery/app/base.py", line 745, in send_task
    amqp.send_task_message(P, name, message, **options)
  File "/home/miroslav/PycharmProjects/Project_nova_poshta-simulator/venv/lib/python3.6/site-packages/celery/app/amqp.py", line 552, in send_task_message
    **properties
  File "/home/miroslav/PycharmProjects/Project_nova_poshta-simulator/venv/lib/python3.6/site-packages/kombu/messaging.py", line 169, in publish
    compression, headers)
  File "/home/miroslav/PycharmProjects/Project_nova_poshta-simulator/venv/lib/python3.6/site-packages/kombu/messaging.py", line 252, in _prepare
    body) = dumps(body, serializer=serializer)
  File "/home/miroslav/PycharmProjects/Project_nova_poshta-simulator/venv/lib/python3.6/site-packages/kombu/serialization.py", line 221, in dumps
    payload = encoder(data)
  File "/usr/lib/python3.6/contextlib.py", line 99, in __exit__
    self.gen.throw(type, value, traceback)
  File "/home/miroslav/PycharmProjects/Project_nova_poshta-simulator/venv/lib/python3.6/site-packages/kombu/serialization.py", line 54, in _reraise_errors
    reraise(wrapper, wrapper(exc), sys.exc_info()[2])
  File "/home/miroslav/PycharmProjects/Project_nova_poshta-simulator/venv/lib/python3.6/site-packages/vine/five.py", line 178, in reraise
    raise value.with_traceback(tb)
  File "/home/miroslav/PycharmProjects/Project_nova_poshta-simulator/venv/lib/python3.6/site-packages/kombu/serialization.py", line 50, in _reraise_errors
    yield
  File "/home/miroslav/PycharmProjects/Project_nova_poshta-simulator/venv/lib/python3.6/site-packages/kombu/serialization.py", line 221, in dumps
    payload = encoder(data)
  File "/home/miroslav/PycharmProjects/Project_nova_poshta-simulator/venv/lib/python3.6/site-packages/kombu/utils/json.py", line 69, in dumps
    **dict(default_kwargs, **kwargs))
  File "/usr/lib/python3.6/json/__init__.py", line 238, in dumps
    **kw).encode(obj)
  File "/usr/lib/python3.6/json/encoder.py", line 199, in encode
    chunks = self.iterencode(o, _one_shot=True)
  File "/usr/lib/python3.6/json/encoder.py", line 257, in iterencode
    return _iterencode(o, 0)
  File "/home/miroslav/PycharmProjects/Project_nova_poshta-simulator/venv/lib/python3.6/site-packages/kombu/utils/json.py", line 59, in default
    return super(JSONEncoder, self).default(o)
  File "/usr/lib/python3.6/json/encoder.py", line 180, in default
    o.__class__.__name__)
kombu.exceptions.EncodeError: Object of type 'User' is not JSON serializable
Not Found: /favicon.ico
Internal Server Error: /np/add_order
Traceback (most recent call last):
  File "/home/miroslav/PycharmProjects/Project_nova_poshta-simulator/venv/lib/python3.6/site-packages/django/core/handlers/exception.py", line 35, in inner
    response = get_response(request)
  File "/home/miroslav/PycharmProjects/Project_nova_poshta-simulator/venv/lib/python3.6/site-packages/django/core/handlers/base.py", line 128, in _get_response
    response = self.process_exception_by_middleware(e, request)
  File "/home/miroslav/PycharmProjects/Project_nova_poshta-simulator/venv/lib/python3.6/site-packages/django/core/handlers/base.py", line 126, in _get_response
    response = wrapped_callback(request, *callback_args, **callback_kwargs)
  File "/home/miroslav/PycharmProjects/Project_nova_poshta-simulator/venv/lib/python3.6/site-packages/django/views/generic/base.py", line 69, in view
    return self.dispatch(request, *args, **kwargs)
  File "/home/miroslav/PycharmProjects/Project_nova_poshta-simulator/venv/lib/python3.6/site-packages/django/views/generic/base.py", line 89, in dispatch
    return handler(request, *args, **kwargs)
  File "/home/miroslav/PycharmProjects/Project_nova_poshta-simulator/venv/lib/python3.6/site-packages/django/views/generic/edit.py", line 142, in post
    return self.form_valid(form)
  File "/home/miroslav/PycharmProjects/Project_nova_poshta-simulator/nova_poshta/main/views.py", line 66, in form_valid
    message_creating.delay(self.request.user.id, form.cleaned_data.get['order_name'])
TypeError: 'builtin_function_or_method' object is not subscriptable
Internal Server Error: /admin/main/vehicle/
Traceback (most recent call last):
  File "/home/miroslav/PycharmProjects/Project_nova_poshta-simulator/venv/lib/python3.6/site-packages/django/db/backends/utils.py", line 85, in _execute
    return self.cursor.execute(sql, params)
  File "/home/miroslav/PycharmProjects/Project_nova_poshta-simulator/venv/lib/python3.6/site-packages/django/db/backends/sqlite3/base.py", line 303, in execute
    return Database.Cursor.execute(self, query, params)
sqlite3.OperationalError: no such column: main_vehicle.total_weight

The above exception was the direct cause of the following exception:

Traceback (most recent call last):
  File "/home/miroslav/PycharmProjects/Project_nova_poshta-simulator/venv/lib/python3.6/site-packages/django/core/handlers/exception.py", line 35, in inner
    response = get_response(request)
  File "/home/miroslav/PycharmProjects/Project_nova_poshta-simulator/venv/lib/python3.6/site-packages/django/core/handlers/base.py", line 128, in _get_response
    response = self.process_exception_by_middleware(e, request)
  File "/home/miroslav/PycharmProjects/Project_nova_poshta-simulator/venv/lib/python3.6/site-packages/django/core/handlers/base.py", line 126, in _get_response
    response = wrapped_callback(request, *callback_args, **callback_kwargs)
  File "/home/miroslav/PycharmProjects/Project_nova_poshta-simulator/venv/lib/python3.6/site-packages/django/contrib/admin/options.py", line 575, in wrapper
    return self.admin_site.admin_view(view)(*args, **kwargs)
  File "/home/miroslav/PycharmProjects/Project_nova_poshta-simulator/venv/lib/python3.6/site-packages/django/utils/decorators.py", line 142, in _wrapped_view
    response = view_func(request, *args, **kwargs)
  File "/home/miroslav/PycharmProjects/Project_nova_poshta-simulator/venv/lib/python3.6/site-packages/django/views/decorators/cache.py", line 44, in _wrapped_view_func
    response = view_func(request, *args, **kwargs)
  File "/home/miroslav/PycharmProjects/Project_nova_poshta-simulator/venv/lib/python3.6/site-packages/django/contrib/admin/sites.py", line 223, in inner
    return view(request, *args, **kwargs)
  File "/home/miroslav/PycharmProjects/Project_nova_poshta-simulator/venv/lib/python3.6/site-packages/django/utils/decorators.py", line 62, in _wrapper
    return bound_func(*args, **kwargs)
  File "/home/miroslav/PycharmProjects/Project_nova_poshta-simulator/venv/lib/python3.6/site-packages/django/utils/decorators.py", line 142, in _wrapped_view
    response = view_func(request, *args, **kwargs)
  File "/home/miroslav/PycharmProjects/Project_nova_poshta-simulator/venv/lib/python3.6/site-packages/django/utils/decorators.py", line 58, in bound_func
    return func.__get__(self, type(self))(*args2, **kwargs2)
  File "/home/miroslav/PycharmProjects/Project_nova_poshta-simulator/venv/lib/python3.6/site-packages/django/contrib/admin/options.py", line 1708, in changelist_view
    selection_note=_('0 of %(cnt)s selected') % {'cnt': len(cl.result_list)},
  File "/home/miroslav/PycharmProjects/Project_nova_poshta-simulator/venv/lib/python3.6/site-packages/django/db/models/query.py", line 254, in __len__
    self._fetch_all()
  File "/home/miroslav/PycharmProjects/Project_nova_poshta-simulator/venv/lib/python3.6/site-packages/django/db/models/query.py", line 1179, in _fetch_all
    self._result_cache = list(self._iterable_class(self))
  File "/home/miroslav/PycharmProjects/Project_nova_poshta-simulator/venv/lib/python3.6/site-packages/django/db/models/query.py", line 53, in __iter__
    results = compiler.execute_sql(chunked_fetch=self.chunked_fetch, chunk_size=self.chunk_size)
  File "/home/miroslav/PycharmProjects/Project_nova_poshta-simulator/venv/lib/python3.6/site-packages/django/db/models/sql/compiler.py", line 1068, in execute_sql
    cursor.execute(sql, params)
  File "/home/miroslav/PycharmProjects/Project_nova_poshta-simulator/venv/lib/python3.6/site-packages/django/db/backends/utils.py", line 100, in execute
    return super().execute(sql, params)
  File "/home/miroslav/PycharmProjects/Project_nova_poshta-simulator/venv/lib/python3.6/site-packages/django/db/backends/utils.py", line 68, in execute
    return self._execute_with_wrappers(sql, params, many=False, executor=self._execute)
  File "/home/miroslav/PycharmProjects/Project_nova_poshta-simulator/venv/lib/python3.6/site-packages/django/db/backends/utils.py", line 77, in _execute_with_wrappers
    return executor(sql, params, many, context)
  File "/home/miroslav/PycharmProjects/Project_nova_poshta-simulator/venv/lib/python3.6/site-packages/django/db/backends/utils.py", line 85, in _execute
    return self.cursor.execute(sql, params)
  File "/home/miroslav/PycharmProjects/Project_nova_poshta-simulator/venv/lib/python3.6/site-packages/django/db/utils.py", line 89, in __exit__
    raise dj_exc_value.with_traceback(traceback) from exc_value
  File "/home/miroslav/PycharmProjects/Project_nova_poshta-simulator/venv/lib/python3.6/site-packages/django/db/backends/utils.py", line 85, in _execute
    return self.cursor.execute(sql, params)
  File "/home/miroslav/PycharmProjects/Project_nova_poshta-simulator/venv/lib/python3.6/site-packages/django/db/backends/sqlite3/base.py", line 303, in execute
    return Database.Cursor.execute(self, query, params)
django.db.utils.OperationalError: no such column: main_vehicle.total_weight
Internal Server Error: /np/add_order
Traceback (most recent call last):
  File "/home/miroslav/PycharmProjects/Project_nova_poshta-simulator/venv/lib/python3.6/site-packages/django/core/handlers/exception.py", line 35, in inner
    response = get_response(request)
  File "/home/miroslav/PycharmProjects/Project_nova_poshta-simulator/venv/lib/python3.6/site-packages/django/core/handlers/base.py", line 128, in _get_response
    response = self.process_exception_by_middleware(e, request)
  File "/home/miroslav/PycharmProjects/Project_nova_poshta-simulator/venv/lib/python3.6/site-packages/django/core/handlers/base.py", line 126, in _get_response
    response = wrapped_callback(request, *callback_args, **callback_kwargs)
  File "/home/miroslav/PycharmProjects/Project_nova_poshta-simulator/venv/lib/python3.6/site-packages/django/views/generic/base.py", line 69, in view
    return self.dispatch(request, *args, **kwargs)
  File "/home/miroslav/PycharmProjects/Project_nova_poshta-simulator/venv/lib/python3.6/site-packages/django/views/generic/base.py", line 89, in dispatch
    return handler(request, *args, **kwargs)
  File "/home/miroslav/PycharmProjects/Project_nova_poshta-simulator/venv/lib/python3.6/site-packages/django/views/generic/edit.py", line 142, in post
    return self.form_valid(form)
  File "/home/miroslav/PycharmProjects/Project_nova_poshta-simulator/nova_poshta/main/views.py", line 66, in form_valid
    message_creating.delay(self.request.user.id, form.cleaned_data.get('order_name'))
  File "/home/miroslav/PycharmProjects/Project_nova_poshta-simulator/venv/lib/python3.6/site-packages/celery/app/task.py", line 408, in delay
    return self.apply_async(args, kwargs)
  File "/home/miroslav/PycharmProjects/Project_nova_poshta-simulator/venv/lib/python3.6/site-packages/celery/app/task.py", line 513, in apply_async
    check_arguments(*(args or ()), **(kwargs or {}))
TypeError: message_creating() missing 1 required positional argument: 'order_name'
Internal Server Error: /np/add_order
Traceback (most recent call last):
  File "/home/miroslav/PycharmProjects/Project_nova_poshta-simulator/venv/lib/python3.6/site-packages/django/core/handlers/exception.py", line 35, in inner
    response = get_response(request)
  File "/home/miroslav/PycharmProjects/Project_nova_poshta-simulator/venv/lib/python3.6/site-packages/django/core/handlers/base.py", line 128, in _get_response
    response = self.process_exception_by_middleware(e, request)
  File "/home/miroslav/PycharmProjects/Project_nova_poshta-simulator/venv/lib/python3.6/site-packages/django/core/handlers/base.py", line 126, in _get_response
    response = wrapped_callback(request, *callback_args, **callback_kwargs)
  File "/home/miroslav/PycharmProjects/Project_nova_poshta-simulator/venv/lib/python3.6/site-packages/django/views/generic/base.py", line 69, in view
    return self.dispatch(request, *args, **kwargs)
  File "/home/miroslav/PycharmProjects/Project_nova_poshta-simulator/venv/lib/python3.6/site-packages/django/views/generic/base.py", line 89, in dispatch
    return handler(request, *args, **kwargs)
  File "/home/miroslav/PycharmProjects/Project_nova_poshta-simulator/venv/lib/python3.6/site-packages/django/views/generic/edit.py", line 142, in post
    return self.form_valid(form)
  File "/home/miroslav/PycharmProjects/Project_nova_poshta-simulator/nova_poshta/main/views.py", line 66, in form_valid
    message_creating.delay(self.request.user.id, form.cleaned_data.get('order_name'))
  File "/home/miroslav/PycharmProjects/Project_nova_poshta-simulator/venv/lib/python3.6/site-packages/celery/app/task.py", line 408, in delay
    return self.apply_async(args, kwargs)
  File "/home/miroslav/PycharmProjects/Project_nova_poshta-simulator/venv/lib/python3.6/site-packages/celery/app/task.py", line 513, in apply_async
    check_arguments(*(args or ()), **(kwargs or {}))
TypeError: message_creating() missing 1 required positional argument: 'order_name'
Internal Server Error: /np/add_order
Traceback (most recent call last):
  File "/home/miroslav/PycharmProjects/Project_nova_poshta-simulator/venv/lib/python3.6/site-packages/django/core/handlers/exception.py", line 35, in inner
    response = get_response(request)
  File "/home/miroslav/PycharmProjects/Project_nova_poshta-simulator/venv/lib/python3.6/site-packages/django/core/handlers/base.py", line 128, in _get_response
    response = self.process_exception_by_middleware(e, request)
  File "/home/miroslav/PycharmProjects/Project_nova_poshta-simulator/venv/lib/python3.6/site-packages/django/core/handlers/base.py", line 126, in _get_response
    response = wrapped_callback(request, *callback_args, **callback_kwargs)
  File "/home/miroslav/PycharmProjects/Project_nova_poshta-simulator/venv/lib/python3.6/site-packages/django/views/generic/base.py", line 69, in view
    return self.dispatch(request, *args, **kwargs)
  File "/home/miroslav/PycharmProjects/Project_nova_poshta-simulator/venv/lib/python3.6/site-packages/django/views/generic/base.py", line 89, in dispatch
    return handler(request, *args, **kwargs)
  File "/home/miroslav/PycharmProjects/Project_nova_poshta-simulator/venv/lib/python3.6/site-packages/django/views/generic/edit.py", line 142, in post
    return self.form_valid(form)
  File "/home/miroslav/PycharmProjects/Project_nova_poshta-simulator/nova_poshta/main/views.py", line 66, in form_valid
    form.save(self.request)
  File "/home/miroslav/PycharmProjects/Project_nova_poshta-simulator/nova_poshta/main/forms.py", line 52, in save
    email=order.getter_email,
  File "/home/miroslav/PycharmProjects/Project_nova_poshta-simulator/venv/lib/python3.6/site-packages/django/db/models/manager.py", line 82, in manager_method
    return getattr(self.get_queryset(), name)(*args, **kwargs)
  File "/home/miroslav/PycharmProjects/Project_nova_poshta-simulator/venv/lib/python3.6/site-packages/django/db/models/query.py", line 403, in get
    self.model._meta.object_name
django.contrib.auth.models.DoesNotExist: User matching query does not exist.
Internal Server Error: /np/add_order
Traceback (most recent call last):
  File "/home/miroslav/PycharmProjects/Project_nova_poshta-simulator/venv/lib/python3.6/site-packages/django/core/handlers/exception.py", line 35, in inner
    response = get_response(request)
  File "/home/miroslav/PycharmProjects/Project_nova_poshta-simulator/venv/lib/python3.6/site-packages/django/core/handlers/base.py", line 128, in _get_response
    response = self.process_exception_by_middleware(e, request)
  File "/home/miroslav/PycharmProjects/Project_nova_poshta-simulator/venv/lib/python3.6/site-packages/django/core/handlers/base.py", line 126, in _get_response
    response = wrapped_callback(request, *callback_args, **callback_kwargs)
  File "/home/miroslav/PycharmProjects/Project_nova_poshta-simulator/venv/lib/python3.6/site-packages/django/views/generic/base.py", line 69, in view
    return self.dispatch(request, *args, **kwargs)
  File "/home/miroslav/PycharmProjects/Project_nova_poshta-simulator/venv/lib/python3.6/site-packages/django/views/generic/base.py", line 89, in dispatch
    return handler(request, *args, **kwargs)
  File "/home/miroslav/PycharmProjects/Project_nova_poshta-simulator/venv/lib/python3.6/site-packages/django/views/generic/edit.py", line 142, in post
    return self.form_valid(form)
  File "/home/miroslav/PycharmProjects/Project_nova_poshta-simulator/nova_poshta/main/views.py", line 66, in form_valid
    form.save(self.request)
  File "/home/miroslav/PycharmProjects/Project_nova_poshta-simulator/nova_poshta/main/forms.py", line 51, in save
    last_name=order.getter_surname,
  File "/home/miroslav/PycharmProjects/Project_nova_poshta-simulator/venv/lib/python3.6/site-packages/django/db/models/manager.py", line 82, in manager_method
    return getattr(self.get_queryset(), name)(*args, **kwargs)
  File "/home/miroslav/PycharmProjects/Project_nova_poshta-simulator/venv/lib/python3.6/site-packages/django/db/models/query.py", line 403, in get
    self.model._meta.object_name
django.contrib.auth.models.DoesNotExist: User matching query does not exist.
Internal Server Error: /np/add_order
Traceback (most recent call last):
  File "/home/miroslav/PycharmProjects/Project_nova_poshta-simulator/venv/lib/python3.6/site-packages/django/core/handlers/exception.py", line 35, in inner
    response = get_response(request)
  File "/home/miroslav/PycharmProjects/Project_nova_poshta-simulator/venv/lib/python3.6/site-packages/django/core/handlers/base.py", line 128, in _get_response
    response = self.process_exception_by_middleware(e, request)
  File "/home/miroslav/PycharmProjects/Project_nova_poshta-simulator/venv/lib/python3.6/site-packages/django/core/handlers/base.py", line 126, in _get_response
    response = wrapped_callback(request, *callback_args, **callback_kwargs)
  File "/home/miroslav/PycharmProjects/Project_nova_poshta-simulator/venv/lib/python3.6/site-packages/django/views/generic/base.py", line 69, in view
    return self.dispatch(request, *args, **kwargs)
  File "/home/miroslav/PycharmProjects/Project_nova_poshta-simulator/venv/lib/python3.6/site-packages/django/views/generic/base.py", line 89, in dispatch
    return handler(request, *args, **kwargs)
  File "/home/miroslav/PycharmProjects/Project_nova_poshta-simulator/venv/lib/python3.6/site-packages/django/views/generic/edit.py", line 142, in post
    return self.form_valid(form)
  File "/home/miroslav/PycharmProjects/Project_nova_poshta-simulator/nova_poshta/main/views.py", line 66, in form_valid
    form.save(self.request)
  File "/home/miroslav/PycharmProjects/Project_nova_poshta-simulator/nova_poshta/main/forms.py", line 64, in save
    password2='123',
  File "/home/miroslav/PycharmProjects/Project_nova_poshta-simulator/venv/lib/python3.6/site-packages/django/contrib/auth/models.py", line 150, in create_user
    return self._create_user(username, email, password, **extra_fields)
  File "/home/miroslav/PycharmProjects/Project_nova_poshta-simulator/venv/lib/python3.6/site-packages/django/contrib/auth/models.py", line 142, in _create_user
    user = self.model(username=username, email=email, **extra_fields)
  File "/home/miroslav/PycharmProjects/Project_nova_poshta-simulator/venv/lib/python3.6/site-packages/django/db/models/base.py", line 495, in __init__
    raise TypeError("'%s' is an invalid keyword argument for this function" % kwarg)
TypeError: 'password1' is an invalid keyword argument for this function
